Workbook

Sheet X
A1: DAFTAR NILAI SEKOLAH MENENGAH KEJURUAN DOA BANGSA
A2: TAHUN PELAJARAN 2024/2025
A3: SEMESTER GENAP
A5: NO | B5: NIS | C5: NAMA SISWA | D5: L/P | F5: KELAS | G5: PENILAIAN
G6: KOMPETENSI KEAHLIAN
G7: DPK 3 REKAYASA PERANGKAT LUNAK
G8: NT | I8: NUH | J8: PTS | K8: PAS | M8: NR | N8: Konversi PAS | O8: Nilai | P8: NILAI
A9: 1 | B9: 2 | C9: 3 | D9: 4 | F9: 5 | G9: JLM ABSENSI | H9: NILAI | I9: P.HARIAN | J9: TEORI | K9: TEORI | L9: PRAKTEK | N9: RAPORT | O9: Raport | P9: RAPORT
A10: 1 | B10: 242501001 | C10: ALVIN PRASETIA | D10: √ | F10: ACP | G10: 0 | H10: =IF(G10>15,"84",IF(G10>7,"78","60")) -> 60 | I10: 0 | J10: 0 | K10: 0 | L10: 0 | M10: =AVERAGE(H10:L10) -> 0 | N10: =$M$58+((M10-$M$56)/($M$55-$M$56))*($M$59-$M$58) -> #DIV/0! | O10: =(0.1*G10)+(0.5*I10)+(0.15*J10)+(0.25*M10) -> 0 | P10: =$O$58+((O10-$O$56)/($O$55-$O$56))*($O$59-$O$58) -> #DIV/0! | Q10: RANK POIN BINTANG
A11: 2 | B11: 242501002 | C11: AKBAR MAULANA | D11: √ | F11: ACP | G11: 0 | H11: =IF(G11>15,"84",IF(G11>7,"78","60")) -> 60 | I11: 0 | J11: 0 | K11: 0 | L11: 0 | M11: =AVERAGE(H11:L11) -> 0 | N11: =$M$58+((M11-$M$56)/($M$55-$M$56))*($M$59-$M$58) -> #DIV/0! | O11: =(0.1*G11)+(0.5*I11)+(0.15*J11)+(0.25*M11) -> 0 | P11: =$O$58+((O11-$O$56)/($O$55-$O$56))*($O$59-$O$58) -> #DIV/0!
A12: 3 | B12: 242501003 | C12: FADIL ABDUL AZIZ | D12: √ | F12: ACP | G12: 0 | H12: =IF(G12>15,"84",IF(G12>7,"78","60")) -> 60 | I12: 0 | J12: 0 | K12: 0 | L12: 0 | M12: =AVERAGE(H12:L12) -> 0 | N12: =$M$58+((M12-$M$56)/($M$55-$M$56))*($M$59-$M$58) -> #DIV/0! | O12: =(0.1*G12)+(0.5*I12)+(0.15*J12)+(0.25*M12) -> 0 | P12: =$O$58+((O12-$O$56)/($O$55-$O$56))*($O$59-$O$58) -> #DIV/0! | Q12: <1 | R12: 78
A13: 4 | B13: 242501004 | C13: FAJAR MAULANA NUGRAHA | D13: √ | F13: ACP | G13: 0 | H13: =IF(G13>15,"84",IF(G13>7,"78","60")) -> 60 | I13: 0 | J13: 0 | K13: 0 | L13: 0 | M13: =AVERAGE(H13:L13) -> 0 | N13: =$M$58+((M13-$M$56)/($M$55-$M$56))*($M$59-$M$58) -> #DIV/0! | O13: =(0.1*G13)+(0.5*I13)+(0.15*J13)+(0.25*M13) -> 0 | P13: =$O$58+((O13-$O$56)/($O$55-$O$56))*($O$59-$O$58) -> #DIV/0! | Q13: 1>2 | R13: 80
A14: 5 | B14: 242501105 | C14: KHANSA AZRIZA | E14: √ | F14: ACP | G14: 0 | H14: =IF(G14>15,"84",IF(G14>7,"78","60")) -> 60 | I14: 0 | J14: 0 | K14: 0 | L14: 0 | M14: =AVERAGE(H14:L14) -> 0 | N14: =$M$58+((M14-$M$56)/($M$55-$M$56))*($M$59-$M$58) -> #DIV/0! | O14: =(0.1*G14)+(0.5*I14)+(0.15*J14)+(0.25*M14) -> 0 | P14: =$O$58+((O14-$O$56)/($O$55-$O$56))*($O$59-$O$58) -> #DIV/0! | Q14: 2>5 | R14: 83
A15: 6 | B15: 242501005 | C15: RAYA AULIA NAJMI | D15: √ | F15: ACP | G15: 0 | H15: =IF(G15>15,"84",IF(G15>7,"78","60")) -> 60 | I15: 0 | J15: 0 | K15: 0 | L15: 0 | M15: =AVERAGE(H15:L15) -> 0 | N15: =$M$58+((M15-$M$56)/($M$55-$M$56))*($M$59-$M$58) -> #DIV/0! | O15: =(0.1*G15)+(0.5*I15)+(0.15*J15)+(0.25*M15) -> 0 | P15: =$O$58+((O15-$O$56)/($O$55-$O$56))*($O$59-$O$58) -> #DIV/0! | Q15: 5>10 | R15: 87
A16: 7 | B16: 242501006 | C16: REGINA APRILIYA | E16: √ | F16: ACP | G16: 0 | H16: =IF(G16>15,"84",IF(G16>7,"78","60")) -> 60 | I16: 0 | J16: 0 | K16: 0 | L16: 0 | M16: =AVERAGE(H16:L16) -> 0 | N16: =$M$58+((M16-$M$56)/($M$55-$M$56))*($M$59-$M$58) -> #DIV/0! | O16: =(0.1*G16)+(0.5*I16)+(0.15*J16)+(0.25*M16) -> 0 | P16: =$O$58+((O16-$O$56)/($O$55-$O$56))*($O$59-$O$58) -> #DIV/0! | Q16: 10>13 | R16: 90
A17: 8 | B17: 242501007 | C17: REINHART IMANUEL ARITONANG | D17: √ | F17: ACP | G17: 0 | H17: =IF(G17>15,"84",IF(G17>7,"78","60")) -> 60 | I17: 0 | J17: 0 | K17: 0 | L17: 0 | M17: =AVERAGE(H17:L17) -> 0 | N17: =$M$58+((M17-$M$56)/($M$55-$M$56))*($M$59-$M$58) -> #DIV/0! | O17: =(0.1*G17)+(0.5*I17)+(0.15*J17)+(0.25*M17) -> 0 | P17: =$O$58+((O17-$O$56)/($O$55-$O$56))*($O$59-$O$58) -> #DIV/0! | Q17: 13>20 | R17: 93
A18: 9 | B18: 242501008 | C18: RIVQI WILIAWAN | D18: √ | F18: ACP | G18: 0 | H18: =IF(G18>15,"84",IF(G18>7,"78","60")) -> 60 | I18: 0 | J18: 0 | K18: 0 | L18: 0 | M18: =AVERAGE(H18:L18) -> 0 | N18: =$M$58+((M18-$M$56)/($M$55-$M$56))*($M$59-$M$58) -> #DIV/0! | O18: =(0.1*G18)+(0.5*I18)+(0.15*J18)+(0.25*M18) -> 0 | P18: =$O$58+((O18-$O$56)/($O$55-$O$56))*($O$59-$O$58) -> #DIV/0!
A19: 10 | B19: 242501009 | C19: ZALZA BYLLA OKTAFEVIYANA | E19: √ | F19: ACP | G19: 0 | H19: =IF(G19>15,"84",IF(G19>7,"78","60")) -> 60 | I19: 0 | J19: 0 | K19: 0 | L19: 0 | M19: =AVERAGE(H19:L19) -> 0 | N19: =$M$58+((M19-$M$56)/($M$55-$M$56))*($M$59-$M$58) -> #DIV/0! | O19: =(0.1*G19)+(0.5*I19)+(0.15*J19)+(0.25*M19) -> 0 | P19: =$O$58+((O19-$O$56)/($O$55-$O$56))*($O$59-$O$58) -> #DIV/0!
A20: 11 | B20: 242501010 | C20: ABDUL EPAN | D20: √ | F20: PPLG | G20: 0 | H20: =IF(G20>15,"84",IF(G20>7,"78","60")) -> 60 | I20: 0 | J20: 0 | K20: 0 | L20: 0 | M20: =AVERAGE(H20:L20) -> 0 | N20: =$M$58+((M20-$M$56)/($M$55-$M$56))*($M$59-$M$58) -> #DIV/0! | O20: =(0.1*G20)+(0.5*I20)+(0.15*J20)+(0.25*M20) -> 0 | P20: =$O$58+((O20-$O$56)/($O$55-$O$56))*($O$59-$O$58) -> #DIV/0!
A21: 12 | B21: 242501011 | C21: ALI SATRIYA BAYU | D21: √ | F21: PPLG | G21: 0 | H21: =IF(G21>15,"84",IF(G21>7,"78","60")) -> 60 | I21: 0 | J21: 0 | K21: 0 | L21: 0 | M21: =AVERAGE(H21:L21) -> 0 | N21: =$M$58+((M21-$M$56)/($M$55-$M$56))*($M$59-$M$58) -> #DIV/0! | O21: =(0.1*G21)+(0.5*I21)+(0.15*J21)+(0.25*M21) -> 0 | P21: =$O$58+((O21-$O$56)/($O$55-$O$56))*($O$59-$O$58) -> #DIV/0!
A22: 13 | B22: 242501012 | C22: DAVIN ARYA PUTRA | D22: √ | F22: PPLG | G22: 0 | H22: =IF(G22>15,"84",IF(G22>7,"78","60")) -> 60 | I22: 0 | J22: 0 | K22: 0 | L22: 0 | M22: =AVERAGE(H22:L22) -> 0 | N22: =$M$58+((M22-$M$56)/($M$55-$M$56))*($M$59-$M$58) -> #DIV/0! | O22: =(0.1*G22)+(0.5*I22)+(0.15*J22)+(0.25*M22) -> 0 | P22: =$O$58+((O22-$O$56)/($O$55-$O$56))*($O$59-$O$58) -> #DIV/0!
A23: 14 | B23: 242501013 | C23: DEVANA APRILIYANO ALAMSYAH | D23: √ | F23: PPLG | G23: 0 | H23: =IF(G23>15,"84",IF(G23>7,"78","60")) -> 60 | I23: 0 | J23: 0 | K23: 0 | L23: 0 | M23: =AVERAGE(H23:L23) -> 0 | N23: =$M$58+((M23-$M$56)/($M$55-$M$56))*($M$59-$M$58) -> #DIV/0! | O23: =(0.1*G23)+(0.5*I23)+(0.15*J23)+(0.25*M23) -> 0 | P23: =$O$58+((O23-$O$56)/($O$55-$O$56))*($O$59-$O$58) -> #DIV/0!
A24: 15 | B24: 242501014 | C24: EVANDRA NOER AREZKY | D24: √ | F24: PPLG | G24: 0 | H24: =IF(G24>15,"84",IF(G24>7,"78","60")) -> 60 | I24: 0 | J24: 0 | K24: 0 | L24: 0 | M24: =AVERAGE(H24:L24) -> 0 | N24: =$M$58+((M24-$M$56)/($M$55-$M$56))*($M$59-$M$58) -> #DIV/0! | O24: =(0.1*G24)+(0.5*I24)+(0.15*J24)+(0.25*M24) -> 0 | P24: =$O$58+((O24-$O$56)/($O$55-$O$56))*($O$59-$O$58) -> #DIV/0!
A25: 16 | B25: 242501015 | C25: EZAR RADITYA GUNAWAN | D25: √ | F25: PPLG | G25: 0 | H25: =IF(G25>15,"84",IF(G25>7,"78","60")) -> 60 | I25: 0 | J25: 0 | K25: 0 | L25: 0 | M25: =AVERAGE(H25:L25) -> 0 | N25: =$M$58+((M25-$M$56)/($M$55-$M$56))*($M$59-$M$58) -> #DIV/0! | O25: =(0.1*G25)+(0.5*I25)+(0.15*J25)+(0.25*M25) -> 0 | P25: =$O$58+((O25-$O$56)/($O$55-$O$56))*($O$59-$O$58) -> #DIV/0!
A26: 17 | B26: 242501016 | C26: FAHMI ABDULRAHMAN | D26: √ | F26: PPLG | G26: 0 | H26: =IF(G26>15,"84",IF(G26>7,"78","60")) -> 60 | I26: 0 | J26: 0 | K26: 0 | L26: 0 | M26: =AVERAGE(H26:L26) -> 0 | N26: =$M$58+((M26-$M$56)/($M$55-$M$56))*($M$59-$M$58) -> #DIV/0! | O26: =(0.1*G26)+(0.5*I26)+(0.15*J26)+(0.25*M26) -> 0 | P26: =$O$58+((O26-$O$56)/($O$55-$O$56))*($O$59-$O$58) -> #DIV/0!
A27: 18 | B27: 242501017 | C27: FARIZ ALBA | D27: √ | F27: PPLG | G27: 0 | H27: =IF(G27>15,"84",IF(G27>7,"78","60")) -> 60 | I27: 0 | J27: 0 | K27: 0 | L27: 0 | M27: =AVERAGE(H27:L27) -> 0 | N27: =$M$58+((M27-$M$56)/($M$55-$M$56))*($M$59-$M$58) -> #DIV/0! | O27: =(0.1*G27)+(0.5*I27)+(0.15*J27)+(0.25*M27) -> 0 | P27: =$O$58+((O27-$O$56)/($O$55-$O$56))*($O$59-$O$58) -> #DIV/0!
A28: 19 | B28: 242501018 | C28: GIA ANANDA SAFITRI | E28: √ | F28: PPLG | G28: 0 | H28: =IF(G28>15,"84",IF(G28>7,"78","60")) -> 60 | I28: 0 | J28: 0 | K28: 0 | L28: 0 | M28: =AVERAGE(H28:L28) -> 0 | N28: =$M$58+((M28-$M$56)/($M$55-$M$56))*($M$59-$M$58) -> #DIV/0! | O28: =(0.1*G28)+(0.5*I28)+(0.15*J28)+(0.25*M28) -> 0 | P28: =$O$58+((O28-$O$56)/($O$55-$O$56))*($O$59-$O$58) -> #DIV/0!
A29: 20 | B29: 242501019 | C29: HAIKAL BUDIANSYAH | D29: √ | F29: PPLG | G29: 0 | H29: =IF(G29>15,"84",IF(G29>7,"78","60")) -> 60 | I29: 0 | J29: 0 | K29: 0 | L29: 0 | M29: =AVERAGE(H29:L29) -> 0 | N29: =$M$58+((M29-$M$56)/($M$55-$M$56))*($M$59-$M$58) -> #DIV/0! | O29: =(0.1*G29)+(0.5*I29)+(0.15*J29)+(0.25*M29) -> 0 | P29: =$O$58+((O29-$O$56)/($O$55-$O$56))*($O$59-$O$58) -> #DIV/0!
A30: 21 | B30: 242501020 | C30: INDRI ANGGRAENI | E30: √ | F30: PPLG | G30: 0 | H30: =IF(G30>15,"84",IF(G30>7,"78","60")) -> 60 | I30: 0 | J30: 0 | K30: 0 | L30: 0 | M30: =AVERAGE(H30:L30) -> 0 | N30: =$M$58+((M30-$M$56)/($M$55-$M$56))*($M$59-$M$58) -> #DIV/0! | O30: =(0.1*G30)+(0.5*I30)+(0.15*J30)+(0.25*M30) -> 0 | P30: =$O$58+((O30-$O$56)/($O$55-$O$56))*($O$59-$O$58) -> #DIV/0!
A31: 22 | B31: 242501021 | C31: INDRIYANI FITRIYASARI | E31: √ | F31: PPLG | G31: 0 | H31: =IF(G31>15,"84",IF(G31>7,"78","60")) -> 60 | I31: 0 | J31: 0 | K31: 0 | L31: 0 | M31: =AVERAGE(H31:L31) -> 0 | N31: =$M$58+((M31-$M$56)/($M$55-$M$56))*($M$59-$M$58) -> #DIV/0! | O31: =(0.1*G31)+(0.5*I31)+(0.15*J31)+(0.25*M31) -> 0 | P31: =$O$58+((O31-$O$56)/($O$55-$O$56))*($O$59-$O$58) -> #DIV/0!
A32: 23 | B32: 242501022 | C32: JANPETER SEBASTIAN PANDIANGAN | D32: √ | F32: PPLG | G32: 0 | H32: =IF(G32>15,"84",IF(G32>7,"78","60")) -> 60 | I32: 0 | J32: 0 | K32: 0 | L32: 0 | M32: =AVERAGE(H32:L32) -> 0 | N32: =$M$58+((M32-$M$56)/($M$55-$M$56))*($M$59-$M$58) -> #DIV/0! | O32: =(0.1*G32)+(0.5*I32)+(0.15*J32)+(0.25*M32) -> 0 | P32: =$O$58+((O32-$O$56)/($O$55-$O$56))*($O$59-$O$58) -> #DIV/0!
A33: 24 | B33: 242501023 | C33: KAYLA VEBRIYANA | E33: √ | F33: PPLG | G33: 0 | H33: =IF(G33>15,"84",IF(G33>7,"78","60")) -> 60 | I33: 0 | J33: 0 | K33: 0 | L33: 0 | M33: =AVERAGE(H33:L33) -> 0 | N33: =$M$58+((M33-$M$56)/($M$55-$M$56))*($M$59-$M$58) -> #DIV/0! | O33: =(0.1*G33)+(0.5*I33)+(0.15*J33)+(0.25*M33) -> 0 | P33: =$O$58+((O33-$O$56)/($O$55-$O$56))*($O$59-$O$58) -> #DIV/0!
A34: 25 | B34: 242501024 | C34: KHAYYIRA HANIFA AZ-ZAHRA | E34: √ | F34: PPLG | G34: 0 | H34: =IF(G34>15,"84",IF(G34>7,"78","60")) -> 60 | I34: 0 | J34: 0 | K34: 0 | L34: 0 | M34: =AVERAGE(H34:L34) -> 0 | N34: =$M$58+((M34-$M$56)/($M$55-$M$56))*($M$59-$M$58) -> #DIV/0! | O34: =(0.1*G34)+(0.5*I34)+(0.15*J34)+(0.25*M34) -> 0 | P34: =$O$58+((O34-$O$56)/($O$55-$O$56))*($O$59-$O$58) -> #DIV/0!
A35: 26 | B35: 242501026 | C35: M. RUSTANDI | D35: √ | F35: PPLG | G35: 0 | H35: =IF(G35>15,"84",IF(G35>7,"78","60")) -> 60 | I35: 0 | J35: 0 | K35: 0 | L35: 0 | M35: =AVERAGE(H35:L35) -> 0 | N35: =$M$58+((M35-$M$56)/($M$55-$M$56))*($M$59-$M$58) -> #DIV/0! | O35: =(0.1*G35)+(0.5*I35)+(0.15*J35)+(0.25*M35) -> 0 | P35: =$O$58+((O35-$O$56)/($O$55-$O$56))*($O$59-$O$58) -> #DIV/0!
A36: 27 | B36: 242501027 | C36: MARISA | E36: √ | F36: PPLG | G36: 0 | H36: =IF(G36>15,"84",IF(G36>7,"78","60")) -> 60 | I36: 0 | J36: 0 | K36: 0 | L36: 0 | M36: =AVERAGE(H36:L36) -> 0 | N36: =$M$58+((M36-$M$56)/($M$55-$M$56))*($M$59-$M$58) -> #DIV/0! | O36: =(0.1*G36)+(0.5*I36)+(0.15*J36)+(0.25*M36) -> 0 | P36: =$O$58+((O36-$O$56)/($O$55-$O$56))*($O$59-$O$58) -> #DIV/0!
A37: 28 | B37: 242501028 | C37: MOCH PAISAL LUTHFI | D37: √ | F37: PPLG | G37: 0 | H37: =IF(G37>15,"84",IF(G37>7,"78","60")) -> 60 | I37: 0 | J37: 0 | K37: 0 | L37: 0 | M37: =AVERAGE(H37:L37) -> 0 | N37: =$M$58+((M37-$M$56)/($M$55-$M$56))*($M$59-$M$58) -> #DIV/0! | O37: =(0.1*G37)+(0.5*I37)+(0.15*J37)+(0.25*M37) -> 0 | P37: =$O$58+((O37-$O$56)/($O$55-$O$56))*($O$59-$O$58) -> #DIV/0!
A38: 29 | B38: 242501030 | C38: MUHAMAD LUGI ALPARIZI | D38: √ | F38: PPLG | G38: 0 | H38: =IF(G38>15,"84",IF(G38>7,"78","60")) -> 60 | I38: 0 | J38: 0 | K38: 0 | L38: 0 | M38: =AVERAGE(H38:L38) -> 0 | N38: =$M$58+((M38-$M$56)/($M$55-$M$56))*($M$59-$M$58) -> #DIV/0! | O38: =(0.1*G38)+(0.5*I38)+(0.15*J38)+(0.25*M38) -> 0 | P38: =$O$58+((O38-$O$56)/($O$55-$O$56))*($O$59-$O$58) -> #DIV/0!
A39: 30 | B39: 242501031 | C39: MUHAMMAD BILAL ALHABSY | D39: √ | F39: PPLG | G39: 0 | H39: =IF(G39>15,"84",IF(G39>7,"78","60")) -> 60 | I39: 0 | J39: 0 | K39: 0 | L39: 0 | M39: =AVERAGE(H39:L39) -> 0 | N39: =$M$58+((M39-$M$56)/($M$55-$M$56))*($M$59-$M$58) -> #DIV/0! | O39: =(0.1*G39)+(0.5*I39)+(0.15*J39)+(0.25*M39) -> 0 | P39: =$O$58+((O39-$O$56)/($O$55-$O$56))*($O$59-$O$58) -> #DIV/0!
A40: 31 | B40: 242501032 | C40: NISEU BIL HASNA | E40: √ | F40: PPLG | G40: 0 | H40: =IF(G40>15,"84",IF(G40>7,"78","60")) -> 60 | I40: 0 | J40: 0 | K40: 0 | L40: 0 | M40: =AVERAGE(H40:L40) -> 0 | N40: =$M$58+((M40-$M$56)/($M$55-$M$56))*($M$59-$M$58) -> #DIV/0! | O40: =(0.1*G40)+(0.5*I40)+(0.15*J40)+(0.25*M40) -> 0 | P40: =$O$58+((O40-$O$56)/($O$55-$O$56))*($O$59-$O$58) -> #DIV/0!
A41: 32 | B41: 242501033 | C41: NOVA NOPIANA | E41: √ | F41: PPLG | G41: 0 | H41: =IF(G41>15,"84",IF(G41>7,"78","60")) -> 60 | I41: 0 | J41: 0 | K41: 0 | L41: 0 | M41: =AVERAGE(H41:L41) -> 0 | N41: =$M$58+((M41-$M$56)/($M$55-$M$56))*($M$59-$M$58) -> #DIV/0! | O41: =(0.1*G41)+(0.5*I41)+(0.15*J41)+(0.25*M41) -> 0 | P41: =$O$58+((O41-$O$56)/($O$55-$O$56))*($O$59-$O$58) -> #DIV/0!
...

Sheet D.SISWA
A1: NO | B1: NIS | C1: NAMA SISWA | D1: KELAS
A5: 1 | B5: 2 | C5: 3 | D5: 4
A6: 1 | B6: 242501001 | C6: ALVIN PRASETIA | D6: XI ACP
A7: 2 | B7: 242501002 | C7: AKBAR MAULANA | D7: XI ACP
A8: 3 | B8: 242501003 | C8: FADIL ABDUL AZIZ | D8: XI ACP
A9: 4 | B9: 242501004 | C9: FAJAR MAULANA NUGRAHA | D9: XI ACP
A10: 5 | B10: 242501105 | C10: KHANSA AZRIZA | D10: XI ACP
A11: 6 | B11: 242501005 | C11: RAYA AULIA NAJMI | D11: XI ACP
A12: 7 | B12: 242501006 | C12: SARAH ANGGI APIKA Z | D12: XI ACP
A13: 8 | B13: 242501007 | C13: REINHART IMANUEL ARITONANG | D13: XI ACP
A14: 9 | B14: 242501008 | C14: RIVQI WILIAWAN | D14: XI ACP
A15: 10 | B15: 242502116 | C15: SRI RAHAYU | D15: XI ACP
A16: 11 | B16: 242501009 | C16: ZALZA BYLLA OKTAFEVIYANA | D16: XI ACP
A17: 12 | B17: 242501010 | C17: ABDUL EPAN | D17: XI RPL
... A98: 93 | B98: 232401054 | C98: VIRZY PRATAMA | D98: XII RPL
C99: ALDIANSAH | D99: X ACP
C100: ALIEF SANJANI | D100: X ACP
C101: CANZA YUDIA MULYA | D101: X ACP
C102: DEFIN PRASETYA | D102: X ACP
C103: FIKRI FAHRIANSAH | D103: X ACP
C104: JISVI DWI ANDREANS | D104: X ACP
C105: KENZI REYNALDI | D105: X ACP
C106: LIANA NARASAKI | D106: X ACP
C107: FADIL BAIHAQI | D107: X ACP
C108: MAULIDA | D108: X ACP
C109: MIRAJ AKBAR PA | D109: X ACP
C110: MUHAMMAD DAVID | D110: X ACP
... C121: ANDHIKA SAPUTRA | D121: X ACP

Sheet XI
A1: DAFTAR NILAI SEKOLAH MENENGAH KEJURUAN DOA BANGSA
A2: TAHUN PELAJARAN 2024/2025
A3: REKAYASA PERANGKAT LUNAK
A5: NO | B5: NIS | C5: NAMA SISWA | D5: L/P | F5: KELAS | G5: PENILAIAN | P5: PENILAIAN | U5: PENILAIAN
G6: KOMPETENSI KEAHLIAN | P6: KOMPETENSI KEAHLIAN | U6: KOMPETENSI KEAHLIAN
G7: BASIS DATA | P7: IOT | U7: PPB
G8: NT | H8: NUH | I8: PTS | J8: PAS | L8: NR | M8: NILAI | N8: Nilai | P8: PTS | Q8: PAS | R8: NILAI | S8: Nilai | U8: PTS | V8: PAS | W8: Konversi PAS | X8: Nilai
A9: 1 | B9: 2 | C9: 3 | D9: 4 | F9: 5 | G9: ABSENSI | H9: P.HARIAN | I9: TEORI | J9: TEORI | K9: PRAKTEK | M9: RAPORT | N9: Raport | P9: TEORI | Q9: TEORI | R9: RAPORT | S9: Raport | U9: TEORI | V9: TEORI | W9: RAPORT | X9: Raport
A10: 1 | B10: 232401001 | C10: ALGAM RISGI SUGIRMAN | D10: √ | F10: ACP | G10: 82 | H10: =AE10 -> 32 | I10: 48 | J10: 97 | K10: 83 | L10: =AVERAGE(J10:K10) -> 90 | M10: =$N$62+((N10-$N$60)/($N$59-$N$60))*($N$63-$N$62) -> 81.173529 | N10: =(0.1*G10)+(0.5*H10)+(0.15*I10)+(0.25*L10) -> 53.9 | P10: =I10 -> 48 | Q10: 93 | R10: =$S$62+((S10-$S$60)/($S$59-$S$60))*($S$63-$S$62) -> 83.081348 | S10: =(0.1*G10)+(0.5*H10)+(0.15*P10)+(0.25*Q10) -> 54.65 | U10: =I10 -> 48 | V10: 93 | W10: =$X$62+((X10-$X$60)/($X$59-$X$60))*($X$63-$X$62) -> 83.132832 | X10: =(0.1*G10)+(0.5*H10)+(0.15*U10)+(0.25*V10) -> 54.65 | Z10: 0 | AA10: 80 | AB10: 80 | AC10: 0 | AD10: 0 | AE10: =AVERAGE(Z10:AD10) -> 32
A11: 2 | B11: 232401002 | C11: CIKAL PUTRA SUBRANI | D11: √ | F11: ACP | G11: 82 | H11: =AE11 -> 32 | I11: 0 | J11: 93 | K11: 0 | L11: =AVERAGE(J11:K11) -> 46.5 | M11: =$N$62+((N11-$N$60)/($N$59-$N$60))*($N$63-$N$62) -> 81.899265 | N11: =(G11*0.5)+(H11*0.15)+(I11*0.1)+(L11*0.25) -> 57.425 | P11: =I11 -> 0 | Q11: 89 | R11: =$S$62+((S11-$S$60)/($S$59-$S$60))*($S$63-$S$62) -> 82.272802 | S11: =(0.1*G11)+(0.5*H11)+(0.15*P11)+(0.25*Q11) -> 46.45 | U11: =I11 -> 0 | V11: 93 | W11: =$X$62+((X11-$X$60)/($X$59-$X$60))*($X$63-$X$62) -> 82.411028 | X11: =(0.1*G11)+(0.5*H11)+(0.15*U11)+(0.25*V11) -> 47.45 | Z11: 80 | AA11: 80 | AB11: 0 | AC11: 0 | AD11: 0 | AE11: =AVERAGE(Z11:AD11) -> 32
A12: 3 | B12: 232401003 | C12: DODI ARIL FAUZI | D12: √ | F12: ACP | G12: 82 | H12: =AE12 -> 48 | I12: 48 | J12: 91 | K12: 83 | L12: =AVERAGE(J12:K12) -> 87 | M12: =$N$62+((N12-$N$60)/($N$59-$N$60))*($N$63-$N$62) -> 85.466176 | N12: =(G12*0.5)+(H12*0.15)+(I12*0.1)+(L12*0.25) -> 74.75 | P12: =I12 -> 48 | Q12: 89 | R12: =$S$62+((S12-$S$60)/($S$59-$S$60))*($S$63-$S$62) -> 83.771569 | S12: =(0.1*G12)+(0.5*H12)+(0.15*P12)+(0.25*Q12) -> 61.65 | U12: =I12 -> 48 | V12: 93 | W12: =$X$62+((X12-$X$60)/($X$59-$X$60))*($X$63-$X$62) -> 83.934837 | X12: =(0.1*G12)+(0.5*H12)+(0.15*U12)+(0.25*V12) -> 62.65 | Z12: 80 | AA12: 80 | AB12: 80 | AC12: 0 | AD12: 0 | AE12: =AVERAGE(Z12:AD12) -> 48
A13: 5 | B13: 232401005 | C13: EKI APRIANSYAH | D13: √ | F13: ACP | G13: 82 | H13: =AE13 -> 65 | I13: 40 | J13: 91 | K13: 83 | L13: =AVERAGE(J13:K13) -> 87 | M13: =$N$62+((N13-$N$60)/($N$59-$N$60))*($N$63-$N$62) -> 85.826471 | N13: =(G13*0.5)+(H13*0.15)+(I13*0.1)+(L13*0.25) -> 76.5 | P13: =I13 -> 40 | Q13: 93 | R13: =$S$62+((S13-$S$60)/($S$59-$S$60))*($S$63-$S$62) -> 84.589975 | S13: =(0.1*G13)+(0.5*H13)+(0.15*P13)+(0.25*Q13) -> 69.95 | U13: =I13 -> 40 | V13: 75 | W13: =$X$62+((X13-$X$60)/($X$59-$X$60))*($X$63-$X$62) -> 84.215539 | X13: =(0.1*G13)+(0.5*H13)+(0.15*U13)+(0.25*V13) -> 65.45 | Z13: 80 | AA13: 80 | AB13: 80 | AC13: 85 | AD13: 0 | AE13: =AVERAGE(Z13:AD13) -> 65
A14: 4 | B14: 232401004 | C14: ENENG SALSA NABILA | E14: √ | F14: ACP | G14: 82 | H14: =AE14 -> 16 | I14: 48 | J14: 0 | K14: 0 | L14: =AVERAGE(J14:K14) -> 0 | M14: =$N$62+((N14-$N$60)/($N$59-$N$60))*($N$63-$N$62) -> 80 | N14: =(G14*0.5)+(H14*0.15)+(I14*0.1)+(L14*0.25) -> 48.2 | P14: =I14 -> 48 | Q14: 0 | R14: =$S$62+((S14-$S$60)/($S$59-$S$60))*($S$63-$S$62) -> 80 | S14: =(0.1*G14)+(0.5*H14)+(0.15*P14)+(0.25*Q14) -> 23.4 | U14: =I14 -> 48 | V14: 0 | W14: =$X$62+((X14-$X$60)/($X$59-$X$60))*($X$63-$X$62) -> 80 | X14: =(0.1*G14)+(0.5*H14)+(0.15*U14)+(0.25*V14) -> 23.4 | Z14: 80 | AA14: 0 | AB14: 0 | AC14: 0 | AD14: 0 | AE14: =AVERAGE(Z14:AD14) -> 16
A15: 6 | B15: 232401006 | C15: ERWIN SUHERMAN | D15: √ | F15: ACP | G15: 82 | H15: =AE15 -> 64.4 | I15: 52 | J15: 95 | K15: 83 | L15: =AVERAGE(J15:K15) -> 89 | M15: =$N$62+((N15-$N$60)/($N$59-$N$60))*($N$63-$N$62) -> 86.157941 | N15: =(G15*0.5)+(H15*0.15)+(I15*0.1)+(L15*0.25) -> 78.11 | P15: =I15 -> 52 | Q15: 93 | R15: =$S$62+((S15-$S$60)/($S$59-$S$60))*($S$63-$S$62) -> 84.73788 | S15: =(0.1*G15)+(0.5*H15)+(0.15*P15)+(0.25*Q15) -> 71.45 | U15: =I15 -> 52 | V15: 93 | W15: =$X$62+((X15-$X$60)/($X$59-$X$60))*($X$63-$X$62) -> 84.817043 | X15: =(0.1*G15)+(0.5*H15)+(0.15*U15)+(0.25*V15) -> 71.45 | Z15: 80 | AA15: 82 | AB15: 80 | AC15: 80 | AD15: 0 | AE15: =AVERAGE(Z15:AD15) -> 64.4
A16: 7 | B16: 232401007 | C16: FAUZAN SYA'BAN NUR'ISLAM | D16: √ | F16: ACP | G16: 82 | H16: =AE16 -> 49 | I16: 56 | J16: 93 | K16: 83 | L16: =AVERAGE(J16:K16) -> 88 | M16: =$N$62+((N16-$N$60)/($N$59-$N$60))*($N$63-$N$62) -> 85.713235 | N16: =(G16*0.5)+(H16*0.15)+(I16*0.1)+(L16*0.25) -> 75.95 | P16: =I16 -> 56 | Q16: 87 | R16: =$S$62+((S16-$S$60)/($S$59-$S$60))*($S$63-$S$62) -> 83.889893 | S16: =(0.1*G16)+(0.5*H16)+(0.15*P16)+(0.25*Q16) -> 62.85 | U16: =I16 -> 56 | V16: 91 | W16: =$X$62+((X16-$X$60)/($X$59-$X$60))*($X$63-$X$62) -> 84.055138 | X16: =(0.1*G16)+(0.5*H16)+(0.15*U16)+(0.25*V16) -> 63.85 | Z16: 80 | AA16: 80 | AB16: 85 | AC16: 0 | AD16: 0 | AE16: =AVERAGE(Z16:AD16) -> 49
A17: 8 | B17: 232401008 | C17: HERMAWAN ANGGARA | E17: √ | F17: ACP | G17: 82 | H17: =AE17 -> 16 | I17: 40 | J17: 97 | K17: 0 | L17: =AVERAGE(J17:K17) -> 48.5 | M17: =$N$62+((N17-$N$60)/($N$59-$N$60))*($N$63-$N$62) -> 82.331618 | N17: =(G17*0.5)+(H17*0.15)+(I17*0.1)+(L17*0.25) -> 59.525 | P17: =I17 -> 40 | Q17: 91 | R17: =$S$62+((S17-$S$60)/($S$59-$S$60))*($S$63-$S$62) -> 82.124897 | S17: =(0.1*G17)+(0.5*H17)+(0.15*P17)+(0.25*Q17) -> 44.95 | U17: =I17 -> 40 | V17: 91 | W17: =$X$62+((X17-$X$60)/($X$59-$X$60))*($X$63-$X$62) -> 82.160401 | X17: =(0.1*G17)+(0.5*H17)+(0.15*U17)+(0.25*V17) -> 44.95 | Z17: 80 | AA17: 0 | AB17: 0 | AC17: 0 | AD17: 0 | AE17: =AVERAGE(Z17:AD17) -> 16
A18: 9 | B18: 232401009 | C18: JANNATA TSAMANIYA ARSYISTAWAA | D18: √ | F18: ACP | G18: 82 | H18: =AE18 -> 32 | I18: 56 | J18: 97 | K18: 0 | L18: =AVERAGE(J18:K18) -> 48.5 | M18: =$N$62+((N18-$N$60)/($N$59-$N$60))*($N$63-$N$62) -> 83.155147 | N18: =(G18*0.5)+(H18*0.15)+(I18*0.1)+(L18*0.25) -> 63.525 | P18: =I18 -> 56 | Q18: 91 | R18: =$S$62+((S18-$S$60)/($S$59-$S$60))*($S$63-$S$62) -> 83.15037 | S18: =(0.1*G18)+(0.5*H18)+(0.15*P18)+(0.25*Q18) -> 55.35 | U18: =I18 -> 56 | V18: 93 | W18: =$X$62+((X18-$X$60)/($X$59-$X$60))*($X$63-$X$62) -> 83.253133 | X18: =(0.1*G18)+(0.5*H18)+(0.15*U18)+(0.25*V18) -> 55.85 | Z18: 80 | AA18: 80 | AB18: 0 | AC18: 0 | AD18: 0 | AE18: =AVERAGE(Z18:AD18) -> 32
A19: 10 | B19: 232401011 | C19: KAMILANIYA TSAQILA | D19: √ | F19: ACP | G19: 82 | H19: =AE19 -> 64 | I19: 60 | J19: 95 | K19: 83 | L19: =AVERAGE(J19:K19) -> 89 | M19: =$N$62+((N19-$N$60)/($N$59-$N$60))*($N$63-$N$62) -> 86.310294 | N19: =(G19*0.5)+(H19*0.15)+(I19*0.1)+(L19*0.25) -> 78.85 | P19: =I19 -> 60 | Q19: 91 | R19: =$S$62+((S19-$S$60)/($S$59-$S$60))*($S$63-$S$62) -> 84.787182 | S19: =(0.1*G19)+(0.5*H19)+(0.15*P19)+(0.25*Q19) -> 71.95 | U19: =I19 -> 60 | V19: 93 | W19: =$X$62+((X19-$X$60)/($X$59-$X$60))*($X$63-$X$62) -> 84.917293 | X19: =(0.1*G19)+(0.5*H19)+(0.15*U19)+(0.25*V19) -> 72.45 | Z19: 80 | AA19: 80 | AB19: 80 | AC19: 80 | AD19: 0 | AE19: =AVERAGE(Z19:AD19) -> 64
A20: 11 | B20: 232401012 | C20: KURNIASANDI AUNURRAFIQ | E20: √ | F20: ACP | G20: 82 | H20: =AE20 -> 48.4 | I20: 68 | J20: 0 | K20: 83 | L20: =AVERAGE(J20:K20) -> 41.5 | M20: =$N$62+((N20-$N$60)/($N$59-$N$60))*($N$63-$N$62) -> 83.548382 | N20: =(G20*0.5)+(H20*0.15)+(I20*0.1)+(L20*0.25) -> 65.435 | P20: =I20 -> 68 | Q20: 93 | R20: =$S$62+((S20-$S$60)/($S$59-$S$60))*($S$63-$S$62) -> 84.185703 | S20: =(0.1*G20)+(0.5*H20)+(0.15*P20)+(0.25*Q20) -> 65.85 | U20: =I20 -> 68 | V20: 93 | W20: =$X$62+((X20-$X$60)/($X$59-$X$60))*($X$63-$X$62) -> 84.255639 | X20: =(0.1*G20)+(0.5*H20)+(0.15*U20)+(0.25*V20) -> 65.85 | Z20: 80 | AA20: 82 | AB20: 80 | AC20: 0 | AD20: 0 | AE20: =AVERAGE(Z20:AD20) -> 48.4
A21: 18 | B21: 232401019 | C21: MIRNA SULASTRI | E21: √ | F21: ACP | G21: 82 | H21: =AE21 -> 64 | I21: 28 | J21: 95 | K21: 83 | L21: =AVERAGE(J21:K21) -> 89 | M21: =$N$62+((N21-$N$60)/($N$59-$N$60))*($N$63-$N$62) -> 85.651471 | N21: =(G21*0.5)+(H21*0.15)+(I21*0.1)+(L21*0.25) -> 75.65 | P21: =I21 -> 28 | Q21: 91 | R21: =$S$62+((S21-$S$60)/($S$59-$S$60))*($S$63-$S$62) -> 84.313887 | S21: =(0.1*G21)+(0.5*H21)+(0.15*P21)+(0.25*Q21) -> 67.15 | U21: =I21 -> 28 | V21: 91 | W21: =$X$62+((X21-$X$60)/($X$59-$X$60))*($X$63-$X$62) -> 84.385965 | X21: =(0.1*G21)+(0.5*H21)+(0.15*U21)+(0.25*V21) -> 67.15 | Z21: 80 | AA21: 80 | AB21: 80 | AC21: 80 | AD21: 0 | AE21: =AVERAGE(Z21:AD21) -> 64
A22: 12 | B22: 232401013 | C22: NISWAH KAMILAH NUR ALA | D22: √ | F22: ACP | G22: 82 | H22: =AE22 -> 32 | I22: 68 | J22: 95 | K22: 83 | L22: =AVERAGE(J22:K22) -> 89 | M22: =$N$62+((N22-$N$60)/($N$59-$N$60))*($N$63-$N$62) -> 85.486765 | N22: =(G22*0.5)+(H22*0.15)+(I22*0.1)+(L22*0.25) -> 74.85 | P22: =I22 -> 68 | Q22: 93 | R22: =$S$62+((S22-$S$60)/($S$59-$S$60))*($S$63-$S$62) -> 83.377157 | S22: =(0.1*G22)+(0.5*H22)+(0.15*P22)+(0.25*Q22) -> 57.65 | U22: =I22 -> 68 | V22: 93 | W22: =$X$62+((X22-$X$60)/($X$59-$X$60))*($X$63-$X$62) -> 83.433584 | X22: =(0.1*G22)+(0.5*H22)+(0.15*U22)+(0.25*V22) -> 57.65 | Z22: 80 | AA22: 80 | AB22: 0 | AC22: 0 | AD22: 0 | AE22: =AVERAGE(Z22:AD22) -> 32
A23: 13 | B23: 232401014 | C23: RAMDAN ALWIANSYAH | D23: √ | F23: ACP | G23: 82 | H23: =AE23 -> 81.4 | I23: 56 | J23: 97 | K23: 83 | L23: =AVERAGE(J23:K23) -> 90 | M23: =$N$62+((N23-$N$60)/($N$59-$N$60))*($N$63-$N$62) -> 86.816765 | N23: =(G23*0.5)+(H23*0.15)+(I23*0.1)+(L23*0.25) -> 81.31 | P23: =I23 -> 56 | Q23: 91 | R23: =$S$62+((S23-$S$60)/($S$59-$S$60))*($S$63-$S$62) -> 85.585867 | S23: =(0.1*G23)+(0.5*H23)+(0.15*P23)+(0.25*Q23) -> 80.05 | U23: =I23 -> 56 | V23: 91 | W23: =$X$62+((X23-$X$60)/($X$59-$X$60))*($X$63-$X$62) -> 85.679198 | X23: =(0.1*G23)+(0.5*H23)+(0.15*U23)+(0.25*V23) -> 80.05 | Z23: 80 | AA23: 82 | AB23: 80 | AC23: 80 | AD23: 85 | AE23: =AVERAGE(Z23:AD23) -> 81.4
A24: 14 | B24: 232401015 | C24: REY GUSTIAWAN | D24: √ | F24: ACP | G24: 82 | H24: =AE24 -> 80.4 | I24: 56 | J24: 97 | K24: 0 | L24: =AVERAGE(J24:K24) -> 48.5 | M24: =$N$62+((N24-$N$60)/($N$59-$N$60))*($N$63-$N$62) -> 84.649853 | N24: =(G24*0.5)+(H24*0.15)+(I24*0.1)+(L24*0.25) -> 70.785 | P24: =I24 -> 56 | Q24: 91 | R24: =$S$62+((S24-$S$60)/($S$59-$S$60))*($S$63-$S$62) -> 85.536565 | S24: =(0.1*G24)+(0.5*H24)+(0.15*P24)+(0.25*Q24) -> 79.55 | U24: =I24 -> 56 | V24: 93 | W24: =$X$62+((X24-$X$60)/($X$59-$X$60))*($X$63-$X$62) -> 85.679198 | X24: =(0.1*G24)+(0.5*H24)+(0.15*U24)+(0.25*V24) -> 80.05 | Z24: 80 | AA24: 82 | AB24: 80 | AC24: 80 | AD24: 80 | AE24: =AVERAGE(Z24:AD24) -> 80.4
A25: 15 | B25: 232401016 | C25: SITI HASANAH | D25: √ | F25: ACP | G25: 82 | H25: =AE25 -> 64 | I25: 36 | J25: 93 | K25: 0 | L25: =AVERAGE(J25:K25) -> 46.5 | M25: =$N$62+((N25-$N$60)/($N$59-$N$60))*($N$63-$N$62) -> 83.628676 | N25: =(G25*0.5)+(H25*0.15)+(I25*0.1)+(L25*0.25) -> 65.825 | P25: =I25 -> 36 | Q25: 87 | R25: =$S$62+((S25-$S$60)/($S$59-$S$60))*($S$63-$S$62) -> 84.333607 | S25: =(0.1*G25)+(0.5*H25)+(0.15*P25)+(0.25*Q25) -> 67.35 | U25: =I25 -> 36 | V25: 73 | W25: =$X$62+((X25-$X$60)/($X$59-$X$60))*($X$63-$X$62) -> 84.055138 | X25: =(0.1*G25)+(0.5*H25)+(0.15*U25)+(0.25*V25) -> 63.85 | Z25: 80 | AA25: 80 | AB25: 80 | AC25: 80 | AD25: 0 | AE25: =AVERAGE(Z25:AD25) -> 64
A26: 16 | B26: 232401017 | C26: SURYANA | E26: √ | F26: ACP | G26: 82 | H26: =AE26 -> 48 | I26: 36 | J26: 0 | K26: 0 | L26: =AVERAGE(J26:K26) -> 0 | M26: =$N$62+((N26-$N$60)/($N$59-$N$60))*($N$63-$N$62) -> 80.741176 | N26: =(G26*0.5)+(H26*0.15)+(I26*0.1)+(L26*0.25) -> 51.8 | P26: =I26 -> 36 | Q26: 87 | R26: =$S$62+((S26-$S$60)/($S$59-$S$60))*($S$63-$S$62) -> 83.544782 | S26: =(0.1*G26)+(0.5*H26)+(0.15*P26)+(0.25*Q26) -> 59.35 | U26: =I26 -> 36 | V26: 93 | W26: =$X$62+((X26-$X$60)/($X$59-$X$60))*($X$63-$X$62) -> 83.754386 | X26: =(0.1*G26)+(0.5*H26)+(0.15*U26)+(0.25*V26) -> 60.85 | Z26: 80 | AA26: 80 | AB26: 80 | AC26: 0 | AD26: 0 | AE26: =AVERAGE(Z26:AD26) -> 48
A27: 17 | B27: 232401018 | C27: TIARA AMANDA PUTRI FATRIANA | E27: √ | F27: ACP | G27: 82 | H27: =AE27 -> 32 | I27: 52 | J27: 95 | K27: 0 | L27: =AVERAGE(J27:K27) -> 47.5 | M27: =$N$62+((N27-$N$60)/($N$59-$N$60))*($N$63-$N$62) -> 83.021324 | N27: =(G27*0.5)+(H27*0.15)+(I27*0.1)+(L27*0.25) -> 62.875 | P27: =I27 -> 52 | Q27: 87 | R27: =$S$62+((S27-$S$60)/($S$59-$S$60))*($S$63-$S$62) -> 82.992605 | S27: =(0.1*G27)+(0.5*H27)+(0.15*P27)+(0.25*Q27) -> 53.75 | U27: =I27 -> 52 | V27: 91 | W27: =$X$62+((X27-$X$60)/($X$59-$X$60))*($X$63-$X$62) -> 83.142857 | X27: =(0.1*G27)+(0.5*H27)+(0.15*U27)+(0.25*V27) -> 54.75 | Z27: 80 | AA27: 80 | AB27: 0 | AC27: 0 | AD27: 0 | AE27: =AVERAGE(Z27:AD27) -> 32
A28: 19 | B28: 232401020 | C28: WAHID DICKY NUGROHO | D28: √ | F28: ACP | G28: 82 | H28: =AE28 -> 32 | I28: 36 | J28: 97 | K28: 83 | L28: =AVERAGE(J28:K28) -> 90 | M28: =$N$62+((N28-$N$60)/($N$59-$N$60))*($N$63-$N$62) -> 84.879412 | N28: =(G28*0.5)+(H28*0.15)+(I28*0.1)+(L28*0.25) -> 71.9 | P28: =I28 -> 36 | Q28: 91 | R28: =$S$62+((S28-$S$60)/($S$59-$S$60))*($S$63-$S$62) -> 82.85456 | S28: =(0.1*G28)+(0.5*H28)+(0.15*P28)+(0.25*Q28) -> 52.35 | U28: =I28 -> 36 | V28: 89 | W28: =$X$62+((X28-$X$60)/($X$59-$X$60))*($X$63-$X$62) -> 82.85213 | X28: =(0.1*G28)+(0.5*H28)+(0.15*U28)+(0.25*V28) -> 51.85 | Z28: 80 | AA28: 80 | AB28: 0 | AC28: 0 | AD28: 0 | AE28: =AVERAGE(Z28:AD28) -> 32
A29: 20 | B29: 232401021 | C29: ABDUL HAKIM | D29: √ | F29: PPLG | G29: 82 | H29: =AE29 -> 81 | I29: 82 | J29: 93 | K29: 0 | L29: =AVERAGE(J29:K29) -> 46.5 | M29: =$N$62+((N29-$N$60)/($N$59-$N$60))*($N$63-$N$62) -> 85.100735 | N29: =(G29*0.5)+(H29*0.15)+(I29*0.1)+(L29*0.25) -> 72.975 | P29: =I29 -> 82 | Q29: 93 | R29: =$S$62+((S29-$S$60)/($S$59-$S$60))*($S$63-$S$62) -> 86 | S29: =(0.1*G29)+(0.5*H29)+(0.15*P29)+(0.25*Q29) -> 84.25 | U29: =I29 -> 82 | V29: 89 | W29: =$X$62+((X29-$X$60)/($X$59-$X$60))*($X$63-$X$62) -> 86 | X29: =(0.1*G29)+(0.5*H29)+(0.15*U29)+(0.25*V29) -> 83.25 | Z29: 80 | AA29: 80 | AB29: 80 | AC29: 80 | AD29: 85 | AE29: =AVERAGE(Z29:AD29) -> 81
A30: 21 | B30: 232401022 | C30: ADITYA PUTRA NURAHMAN | D30: √ | F30: PPLG | G30: 81 | H30: =AE30 -> 81 | I30: 62 | J30: 95 | K30: 83 | L30: =AVERAGE(J30:K30) -> 89 | M30: =$N$62+((N30-$N$60)/($N$59-$N$60))*($N$63-$N$62) -> 86.773529 | N30: =(G30*0.5)+(H30*0.15)+(I30*0.1)+(L30*0.25) -> 81.1 | P30: =I30 -> 62 | Q30: 93 | R30: =$S$62+((S30-$S$60)/($S$59-$S$60))*($S$63-$S$62) -> 85.69433 | S30: =(0.1*G30)+(0.5*H30)+(0.15*P30)+(0.25*Q30) -> 81.15 | U30: =I30 -> 62 | V30: 93 | W30: =$X$62+((X30-$X$60)/($X$59-$X$60))*($X$63-$X$62) -> 85.789474 | X30: =(0.1*G30)+(0.5*H30)+(0.15*U30)+(0.25*V30) -> 81.15 | Z30: 80 | AA30: 80 | AB30: 80 | AC30: 80 | AD30: 85 | AE30: =AVERAGE(Z30:AD30) -> 81
A31: 26 | B31: 232401027 | C31: ADRIAN BAGUS RAMADANI | D31: √ | F31: PPLG | G31: 80 | H31: =AE31 -> 81 | I31: 64 | J31: 93 | K31: 83 | L31: =AVERAGE(J31:K31) -> 88 | M31: =$N$62+((N31-$N$60)/($N$59-$N$60))*($N$63-$N$62) -> 86.660294 | N31: =(G31*0.5)+(H31*0.15)+(I31*0.1)+(L31*0.25) -> 80.55 | P31: =I31 -> 64 | Q31: 87 | R31: =$S$62+((S31-$S$60)/($S$59-$S$60))*($S$63-$S$62) -> 85.566146 | S31: =(0.1*G31)+(0.5*H31)+(0.15*P31)+(0.25*Q31) -> 79.85 | U31: =I31 -> 64 | V31: 87 | W31: =$X$62+((X31-$X$60)/($X$59-$X$60))*($X$63-$X$62) -> 85.659148 | X31: =(0.1*G31)+(0.5*H31)+(0.15*U31)+(0.25*V31) -> 79.85 | Z31: 80 | AA31: 80 | AB31: 80 | AC31: 80 | AD31: 85 | AE31: =AVERAGE(Z31:AD31) -> 81
A32: 22 | B32: 232401023 | C32: AGIL AL PAUJI | D32: √ | F32: PPLG | G32: 82 | H32: =AE32 -> 81 | I32: 0 | J32: 87 | K32: 0 | L32: =AVERAGE(J32:K32) -> 43.5 | M32: =$N$62+((N32-$N$60)/($N$59-$N$60))*($N$63-$N$62) -> 83.258088 | N32: =(G32*0.5)+(H32*0.15)+(I32*0.1)+(L32*0.25) -> 64.025 | P32: =I32 -> 0 | Q32: 93 | R32: =$S$62+((S32-$S$60)/($S$59-$S$60))*($S$63-$S$62) -> 84.787182 | S32: =(0.1*G32)+(0.5*H32)+(0.15*P32)+(0.25*Q32) -> 71.95 | U32: =I32 -> 0 | V32: 93 | W32: =$X$62+((X32-$X$60)/($X$59-$X$60))*($X$63-$X$62) -> 84.867168 | X32: =(0.1*G32)+(0.5*H32)+(0.15*U32)+(0.25*V32) -> 71.95 | Z32: 80 | AA32: 80 | AB32: 80 | AC32: 80 | AD32: 85 | AE32: =AVERAGE(Z32:AD32) -> 81
A33: 23 | B33: 232401024 | C33: AGUNAWAN | D33: √ | F33: PPLG | G33: 82 | H33: =AE33 -> 81 | I33: 64 | J33: 87 | K33: 83 | L33: =AVERAGE(J33:K33) -> 85 | M33: =$N$62+((N33-$N$60)/($N$59-$N$60))*($N$63-$N$62) -> 86.711765 | N33: =(G33*0.5)+(H33*0.15)+(I33*0.1)+(L33*0.25) -> 80.8 | P33: =I33 -> 64 | Q33: 93 | R33: =$S$62+((S33-$S$60)/($S$59-$S$60))*($S$63-$S$62) -> 85.733772 | S33: =(0.1*G33)+(0.5*H33)+(0.15*P33)+(0.25*Q33) -> 81.55 | U33: =I33 -> 64 | V33: 93 | W33: =$X$62+((X33-$X$60)/($X$59-$X$60))*($X$63-$X$62) -> 85.829574 | X33: =(0.1*G33)+(0.5*H33)+(0.15*U33)+(0.25*V33) -> 81.55 | Z33: 80 | AA33: 80 | AB33: 80 | AC33: 80 | AD33: 85 | AE33: =AVERAGE(Z33:AD33) -> 81
A34: 24 | B34: 232401025 | C34: ALI AKBAR NUR SUBHKI | D34: √ | F34: PPLG | G34: 81 | H34: =AE34 -> 81 | I34: 0 | J34: 91 | K34: 83 | L34: =AVERAGE(J34:K34) -> 87 | M34: =$N$62+((N34-$N$60)/($N$59-$N$60))*($N$63-$N$62) -> 85.394118 | N34: =(G34*0.5)+(H34*0.15)+(I34*0.1)+(L34*0.25) -> 74.4 | P34: =I34 -> 0 | Q34: 93 | R34: =$S$62+((S34-$S$60)/($S$59-$S$60))*($S$63-$S$62) -> 84.777321 | S34: =(0.1*G34)+(0.5*H34)+(0.15*P34)+(0.25*Q34) -> 71.85 | U34: =I34 -> 0 | V34: 93 | W34: =$X$62+((X34-$X$60)/($X$59-$X$60))*($X$63-$X$62) -> 84.857143 | X34: =(0.1*G34)+(0.5*H34)+(0.15*U34)+(0.25*V34) -> 71.85 | Z34: 80 | AA34: 80 | AB34: 80 | AC34: 80 | AD34: 85 | AE34: =AVERAGE(Z34:AD34) -> 81
A35: 25 | B35: 232401026 | C35: ALMA DEFAULIA MAHARANI | E35: √ | F35: PPLG | G35: 82 | H35: =AE35 -> 81 | I35: 66 | J35: 91 | K35: 83 | L35: =AVERAGE(J35:K35) -> 87 | M35: =$N$62+((N35-$N$60)/($N$59-$N$60))*($N$63-$N$62) -> 86.855882 | N35: =(G35*0.5)+(H35*0.15)+(I35*0.1)+(L35*0.25) -> 81.5 | P35: =I35 -> 66 | Q35: 93 | R35: =$S$62+((S35-$S$60)/($S$59-$S$60))*($S$63-$S$62) -> 85.763353 | S35: =(0.1*G35)+(0.5*H35)+(0.15*P35)+(0.25*Q35) -> 81.85 | U35: =I35 -> 66 | V35: 87 | W35: =$X$62+((X35-$X$60)/($X$59-$X$60))*($X$63-$X$62) -> 85.709273 | X35: =(0.1*G35)+(0.5*H35)+(0.15*U35)+(0.25*V35) -> 80.35 | Z35: 80 | AA35: 80 | AB35: 80 | AC35: 80 | AD35: 85 | AE35: =AVERAGE(Z35:AD35) -> 81
A36: 27 | B36: 232401028 | C36: ARABI RUDINATA | D36: √ | F36: PPLG | G36: 82 | H36: =AE36 -> 81 | I36: 64 | J36: 59 | K36: 83 | L36: =AVERAGE(J36:K36) -> 71 | M36: =$N$62+((N36-$N$60)/($N$59-$N$60))*($N$63-$N$62) -> 85.991176 | N36: =(G36*0.5)+(H36*0.15)+(I36*0.1)+(L36*0.25) -> 77.3 | P36: =I36 -> 64 | Q36: 89 | R36: =$S$62+((S36-$S$60)/($S$59-$S$60))*($S$63-$S$62) -> 85.635168 | S36: =(0.1*G36)+(0.5*H36)+(0.15*P36)+(0.25*Q36) -> 80.55 | U36: =I36 -> 64 | V36: 93 | W36: =$X$62+((X36-$X$60)/($X$59-$X$60))*($X$63-$X$62) -> 85.829574 | X36: =(0.1*G36)+(0.5*H36)+(0.15*U36)+(0.25*V36) -> 81.55 | Z36: 80 | AA36: 80 | AB36: 80 | AC36: 80 | AD36: 85 | AE36: =AVERAGE(Z36:AD36) -> 81
A37: 28 | B37: 232401029 | C37: ARDIANSYAH | D37: √ | F37: PPLG | G37: 82 | H37: =AE37 -> 81 | I37: 64 | J37: 93 | K37: 0 | L37: =AVERAGE(J37:K37) -> 46.5 | M37: =$N$62+((N37-$N$60)/($N$59-$N$60))*($N$63-$N$62) -> 84.730147 | N37: =(G37*0.5)+(H37*0.15)+(I37*0.1)+(L37*0.25) -> 71.175 | P37: =I37 -> 64 | Q37: 89 | R37: =$S$62+((S37-$S$60)/($S$59-$S$60))*($S$63-$S$62) -> 85.635168 | S37: =(0.1*G37)+(0.5*H37)+(0.15*P37)+(0.25*Q37) -> 80.55 | U37: =I37 -> 64 | V37: 75 | W37: =$X$62+((X37-$X$60)/($X$59-$X$60))*($X$63-$X$62) -> 85.378446 | X37: =(0.1*G37)+(0.5*H37)+(0.15*U37)+(0.25*V37) -> 77.05 | Z37: 80 | AA37: 80 | AB37: 80 | AC37: 80 | AD37: 85 | AE37: =AVERAGE(Z37:AD37) -> 81
A38: 29 | B38: 232401030 | C38: ASTRI LIANTI | E38: √ | F38: PPLG | G38: 82 | H38: =AE38 -> 81 | I38: 68 | J38: 91 | K38: 83 | L38: =AVERAGE(J38:K38) -> 87 | M38: =$N$62+((N38-$N$60)/($N$59-$N$60))*($N$63-$N$62) -> 86.897059 | N38: =(G38*0.5)+(H38*0.15)+(I38*0.1)+(L38*0.25) -> 81.7 | P38: =I38 -> 68 | Q38: 91 | R38: =$S$62+((S38-$S$60)/($S$59-$S$60))*($S$63-$S$62) -> 85.743632 | S38: =(0.1*G38)+(0.5*H38)+(0.15*P38)+(0.25*Q38) -> 81.65 | U38: =I38 -> 68 | V38: 87 | W38: =$X$62+((X38-$X$60)/($X$59-$X$60))*($X$63-$X$62) -> 85.739348 | X38: =(0.1*G38)+(0.5*H38)+(0.15*U38)+(0.25*V38) -> 80.65 | Z38: 80 | AA38: 80 | AB38: 80 | AC38: 80 | AD38: 85 | AE38: =AVERAGE(Z38:AD38) -> 81
A39: 30 | B39: 232401031 | C39: AURA PUTRI RAMADANI | E39: √ | F39: PPLG | G39: 82 | H39: =AE39 -> 81 | I39: 70 | J39: 91 | K39: 83 | L39: =AVERAGE(J39:K39) -> 87 | M39: =$N$62+((N39-$N$60)/($N$59-$N$60))*($N$63-$N$62) -> 86.938235 | N39: =(G39*0.5)+(H39*0.15)+(I39*0.1)+(L39*0.25) -> 81.9 | P39: =I39 -> 70 | Q39: 93 | R39: =$S$62+((S39-$S$60)/($S$59-$S$60))*($S$63-$S$62) -> 85.822514 | S39: =(0.1*G39)+(0.5*H39)+(0.15*P39)+(0.25*Q39) -> 82.45 | U39: =I39 -> 70 | V39: 93 | W39: =$X$62+((X39-$X$60)/($X$59-$X$60))*($X$63-$X$62) -> 85.919799 | X39: =(0.1*G39)+(0.5*H39)+(0.15*U39)+(0.25*V39) -> 82.45 | Z39: 80 | AA39: 80 | AB39: 80 | AC39: 80 | AD39: 85 | AE39: =AVERAGE(Z39:AD39) -> 81
A40: 31 | B40: 232401032 | C40: ERLANGGA WIRADINATA | D40: √ | F40: PPLG | G40: 81 | H40: =AE40 -> 49 | I40: 64 | J40: 83 | K40: 83 | L40: =AVERAGE(J40:K40) -> 83 | M40: =$N$62+((N40-$N$60)/($N$59-$N$60))*($N$63-$N$62) -> 85.517647 | N40: =(G40*0.5)+(H40*0.15)+(I40*0.1)+(L40*0.25) -> 75 | P40: =I40 -> 64 | Q40: 69 | R40: =$S$62+((S40-$S$60)/($S$59-$S$60))*($S$63-$S$62) -> 83.554643 | S40: =(0.1*G40)+(0.5*H40)+(0.15*P40)+(0.25*Q40) -> 59.45 | U40: =I40 -> 64 | V40: 87 | W40: =$X$62+((X40-$X$60)/($X$59-$X$60))*($X$63-$X$62) -> 84.065163 | X40: =(0.1*G40)+(0.5*H40)+(0.15*U40)+(0.25*V40) -> 63.95 | Z40: 80 | AA40: 80 | AB40: 0 | AC40: 0 | AD40: 85 | AE40: =AVERAGE(Z40:AD40) -> 49
A41: 32 | B41: 232401033 | C41: IKHSAN ALFANDI PRATAMA | D41: √ | F41: PPLG | G41: 82 | H41: =AE41 -> 81 | I41: 54 | J41: 93 | K41: 0 | L41: =AVERAGE(J41:K41) -> 46.5 | M41: =$N$62+((N41-$N$60)/($N$59-$N$60))*($N$63-$N$62) -> 84.524265 | N41: =(G41*0.5)+(H41*0.15)+(I41*0.1)+(L41*0.25) -> 70.175 | P41: =I41 -> 54 | Q41: 91 | R41: =$S$62+((S41-$S$60)/($S$59-$S$60))*($S$63-$S$62) -> 85.536565 | S41: =(0.1*G41)+(0.5*H41)+(0.15*P41)+(0.25*Q41) -> 79.55 | U41: =I41 -> 54 | V41: 93 | W41: =$X$62+((X41-$X$60)/($X$59-$X$60))*($X$63-$X$62) -> 85.679198 | X41: =(0.1*G41)+(0.5*H41)+(0.15*U41)+(0.25*V41) -> 80.05 | Z41: 80 | AA41: 80 | AB41: 80 | AC41: 80 | AD41: 85 | AE41: =AVERAGE(Z41:AD41) -> 81
...

Sheet XII
A1: DAFTAR NILAI SEKOLAH MENENGAH KEJURUAN DOA BANGSA
A2: TAHUN PELAJARAN 2024/2025
A3: REKAYASA PERANGKAT LUNAK
A5: NO | B5: NIS | C5: NAMA SISWA | D5: L/P | F5: KELAS | G5: PENILAIAN | P5: PENILAIAN | U5: PENILAIAN | Z5: PROGRES PROJEK PENGAYAAN UKK
G6: KOMPETENSI KEAHLIAN | P6: KOMPETENSI KEAHLIAN | U6: KOMPETENSI KEAHLIAN
G7: BASIS DATA | P7: PWPB | U7: PPB
G8: NT | H8: NUH | I8: PTS | J8: PAS | L8: NR | M8: NILAI | N8: Nilai | P8: PTS | Q8: PAS | R8: NILAI | S8: Nilai | U8: PTS | V8: PAS | W8: Konversi PAS | X8: Nilai
A9: 1 | B9: 2 | C9: 3 | D9: 4 | F9: 5 | G9: ABSENSI | H9: P.HARIAN | I9: TEORI | J9: TEORI | K9: PRAKTEK | M9: RAPORT | N9: Raport | P9: TEORI | Q9: TEORI | R9: RAPORT | S9: Raport | U9: TEORI | V9: TEORI | W9: RAPORT | X9: Raport | Z9: DATABASES | AA9: LOGIN MULTI USER | AB9: TEMPLATING ENGING | AC9: CREATE | AD9: READ | AE9: UPDATE | AF9: DELETE | AG9: SEARCHING | AH9: REPORT
A10: 1 | B10: 222301001 | C10: ADAM PRATAMA | D10: √ | F10: ACP | G10: 77 | H10: 77 | I10: 0 | J10: 71 | K10: 70 | L10: =AVERAGE(J10:K10) -> 70.5 | M10: =$N$64+((N10-$N$62)/($N$61-$N$62))*($N$65-$N$64) -> 83.035088 | N10: =(0.1*G10)+(0.5*H10)+(0.15*I10)+(0.25*L10) -> 63.825 | P10: =I10 -> 0 | Q10: 0 | R10: =$S$64+((S10-$S$62)/($S$61-$S$62))*($S$65-$S$64) -> 83.013913 | S10: =(0.1*G10)+(0.5*H10)+(0.15*P10)+(0.25*Q10) -> 46.2 | U10: 0 | V10: 0 | W10: =$V$64+((V10-$V$62)/($V$61-$V$62))*($V$65-$V$64) -> #DIV/0! | X10: =(G10*0.5)+(H10*0.15)+(U10*0.1)+(W10*0.25) -> #DIV/0!
A11: 2 | B11: 222301003 | C11: ANDRA SYAHRI RAMDANI | D11: √ | F11: ACP | G11: 80 | H11: 85 | I11: 82 | J11: 79 | K11: 82 | L11: =AVERAGE(J11:K11) -> 80.5 | M11: =$N$64+((N11-$N$62)/($N$61-$N$62))*($N$65-$N$64) -> 86.385965 | N11: =(0.1*G11)+(0.5*H11)+(0.15*I11)+(0.25*L11) -> 82.925 | P11: =I11 -> 82 | Q11: 0 | R11: =$S$64+((S11-$S$62)/($S$61-$S$62))*($S$65-$S$64) -> 86.478261 | S11: =(0.1*G11)+(0.5*H11)+(0.15*P11)+(0.25*Q11) -> 62.8 | U11: 0 | V11: 0 | W11: =$V$64+((V11-$V$62)/($V$61-$V$62))*($V$65-$V$64) -> #DIV/0! | X11: =(G11*0.5)+(H11*0.15)+(U11*0.1)+(W11*0.25) -> #DIV/0!
A12: 3 | B12: 222301004 | C12: DANI | D12: √ | F12: ACP | G12: 80 | H12: 85 | I12: 80 | J12: 79 | K12: 86 | L12: =AVERAGE(J12:K12) -> 82.5 | M12: =$N$64+((N12-$N$62)/($N$61-$N$62))*($N$65-$N$64) -> 86.421053 | N12: =(0.1*G12)+(0.5*H12)+(0.15*I12)+(0.25*L12) -> 83.125 | P12: =I12 -> 80 | Q12: 0 | R12: =$S$64+((S12-$S$62)/($S$61-$S$62))*($S$65-$S$64) -> 86.415652 | S12: =(0.1*G12)+(0.5*H12)+(0.15*P12)+(0.25*Q12) -> 62.5 | U12: 0 | V12: 0 | W12: =$V$64+((V12-$V$62)/($V$61-$V$62))*($V$65-$V$64) -> #DIV/0! | X12: =(G12*0.5)+(H12*0.15)+(U12*0.1)+(W12*0.25) -> #DIV/0!
A13: 4 | B13: 222301005 | C13: GLADISYA HARUMI NEGERI | E13: √ | F13: ACP | G13: 80 | H13: 80 | I13: 80 | J13: 79 | K13: 85 | L13: =AVERAGE(J13:K13) -> 82 | M13: =$N$64+((N13-$N$62)/($N$61-$N$62))*($N$65-$N$64) -> 85.960526 | N13: =(0.1*G13)+(0.5*H13)+(0.15*I13)+(0.25*L13) -> 80.5 | P13: =I13 -> 80 | Q13: 0 | R13: =$S$64+((S13-$S$62)/($S$61-$S$62))*($S$65-$S$64) -> 85.893913 | S13: =(0.1*G13)+(0.5*H13)+(0.15*P13)+(0.25*Q13) -> 60 | U13: 0 | V13: 0 | W13: =$V$64+((V13-$V$62)/($V$61-$V$62))*($V$65-$V$64) -> #DIV/0! | X13: =(G13*0.5)+(H13*0.15)+(U13*0.1)+(W13*0.25) -> #DIV/0!
A14: 5 | B14: 222301006 | C14: HASBI MUBAROK | D14: √ | F14: ACP | G14: 80 | H14: 85 | I14: 82 | J14: 75 | K14: 82 | L14: =AVERAGE(J14:K14) -> 78.5 | M14: =$N$64+((N14-$N$62)/($N$61-$N$62))*($N$65-$N$64) -> 86.298246 | N14: =(0.1*G14)+(0.5*H14)+(0.15*I14)+(0.25*L14) -> 82.425 | P14: =I14 -> 82 | Q14: 0 | R14: =$S$64+((S14-$S$62)/($S$61-$S$62))*($S$65-$S$64) -> 86.478261 | S14: =(0.1*G14)+(0.5*H14)+(0.15*P14)+(0.25*Q14) -> 62.8 | U14: 0 | V14: 0 | W14: =$V$64+((V14-$V$62)/($V$61-$V$62))*($V$65-$V$64) -> #DIV/0! | X14: =(G14*0.5)+(H14*0.15)+(U14*0.1)+(W14*0.25) -> #DIV/0!
A15: 6 | B15: 222301007 | C15: MUHAMMAD ALDO AL-TU RIZKI | D15: √ | F15: ACP | G15: 80 | H15: 77 | I15: 80 | J15: 81 | K15: 83 | L15: =AVERAGE(J15:K15) -> 82 | M15: =$N$64+((N15-$N$62)/($N$61-$N$62))*($N$65-$N$64) -> 85.697368 | N15: =(0.1*G15)+(0.5*H15)+(0.15*I15)+(0.25*L15) -> 79 | P15: =I15 -> 80 | Q15: 0 | R15: =$S$64+((S15-$S$62)/($S$61-$S$62))*($S$65-$S$64) -> 85.58087 | S15: =(0.1*G15)+(0.5*H15)+(0.15*P15)+(0.25*Q15) -> 58.5 | U15: 0 | V15: 0 | W15: =$V$64+((V15-$V$62)/($V$61-$V$62))*($V$65-$V$64) -> #DIV/0! | X15: =(G15*0.5)+(H15*0.15)+(U15*0.1)+(W15*0.25) -> #DIV/0!
A16: 7 | B16: 222301008 | C16: MUHAMMAD ALIP ALBUHORI | D16: √ | F16: ACP | G16: 80 | H16: 85 | I16: 82 | J16: 71 | K16: 79 | L16: =AVERAGE(J16:K16) -> 75 | M16: =$N$64+((N16-$N$62)/($N$61-$N$62))*($N$65-$N$64) -> 86.144737 | N16: =(0.1*G16)+(0.5*H16)+(0.15*I16)+(0.25*L16) -> 81.55 | P16: =I16 -> 82 | Q16: 0 | R16: =$S$64+((S16-$S$62)/($S$61-$S$62))*($S$65-$S$64) -> 86.478261 | S16: =(0.1*G16)+(0.5*H16)+(0.15*P16)+(0.25*Q16) -> 62.8 | U16: 0 | V16: 0 | W16: =$V$64+((V16-$V$62)/($V$61-$V$62))*($V$65-$V$64) -> #DIV/0! | X16: =(G16*0.5)+(H16*0.15)+(U16*0.1)+(W16*0.25) -> #DIV/0!
A17: 8 | B17: 222301009 | C17: MUHAMMAD AZRIL MAULANA | D17: √ | F17: ACP | G17: 80 | H17: 85 | I17: 82 | J17: 79 | K17: 80 | L17: =AVERAGE(J17:K17) -> 79.5 | M17: =$N$64+((N17-$N$62)/($N$61-$N$62))*($N$65-$N$64) -> 86.342105 | N17: =(0.1*G17)+(0.5*H17)+(0.15*I17)+(0.25*L17) -> 82.675 | P17: =I17 -> 82 | Q17: 0 | R17: =$S$64+((S17-$S$62)/($S$61-$S$62))*($S$65-$S$64) -> 86.478261 | S17: =(0.1*G17)+(0.5*H17)+(0.15*P17)+(0.25*Q17) -> 62.8 | U17: 0 | V17: 0 | W17: =$V$64+((V17-$V$62)/($V$61-$V$62))*($V$65-$V$64) -> #DIV/0! | X17: =(G17*0.5)+(H17*0.15)+(U17*0.1)+(W17*0.25) -> #DIV/0!
A18: 9 | B18: 222301010 | C18: MUHAMMAD RAKA DEFIAN | D18: √ | F18: ACP | G18: 80 | H18: 85 | I18: 82 | J18: 75 | K18: 82 | L18: =AVERAGE(J18:K18) -> 78.5 | M18: =$N$64+((N18-$N$62)/($N$61-$N$62))*($N$65-$N$64) -> 86.298246 | N18: =(0.1*G18)+(0.5*H18)+(0.15*I18)+(0.25*L18) -> 82.425 | P18: =I18 -> 82 | Q18: 0 | R18: =$S$64+((S18-$S$62)/($S$61-$S$62))*($S$65-$S$64) -> 86.478261 | S18: =(0.1*G18)+(0.5*H18)+(0.15*P18)+(0.25*Q18) -> 62.8 | U18: 0 | V18: 0 | W18: =$V$64+((V18-$V$62)/($V$61-$V$62))*($V$65-$V$64) -> #DIV/0! | X18: =(G18*0.5)+(H18*0.15)+(U18*0.1)+(W18*0.25) -> #DIV/0!
A19: 10 | B19: 222301011 | C19: MUHAMAD SETIAJI | D19: √ | F19: ACP | G19: 80 | H19: 77 | I19: 0 | J19: 0 | K19: 75 | L19: =AVERAGE(J19:K19) -> 37.5 | M19: =$N$64+((N19-$N$62)/($N$61-$N$62))*($N$65-$N$64) -> 81.640351 | N19: =(0.1*G19)+(0.5*H19)+(0.15*I19)+(0.25*L19) -> 55.875 | P19: =I19 -> 0 | Q19: 0 | R19: =$S$64+((S19-$S$62)/($S$61-$S$62))*($S$65-$S$64) -> 83.076522 | S19: =(0.1*G19)+(0.5*H19)+(0.15*P19)+(0.25*Q19) -> 46.5 | U19: 0 | V19: 0 | W19: =$V$64+((V19-$V$62)/($V$61-$V$62))*($V$65-$V$64) -> #DIV/0! | X19: =(G19*0.5)+(H19*0.15)+(U19*0.1)+(W19*0.25) -> #DIV/0!
A20: 11 | B20: 222301012 | C20: PARHAN HAMDALAH | D20: √ | F20: ACP | G20: 80 | H20: 77 | I20: 0 | J20: 79 | K20: 81 | L20: =AVERAGE(J20:K20) -> 80 | M20: =$N$64+((N20-$N$62)/($N$61-$N$62))*($N$65-$N$64) -> 83.504386 | N20: =(0.1*G20)+(0.5*H20)+(0.15*I20)+(0.25*L20) -> 66.5 | P20: =I20 -> 0 | Q20: 0 | R20: =$S$64+((S20-$S$62)/($S$61-$S$62))*($S$65-$S$64) -> 83.076522 | S20: =(0.1*G20)+(0.5*H20)+(0.15*P20)+(0.25*Q20) -> 46.5 | U20: 0 | V20: 0 | W20: =$V$64+((V20-$V$62)/($V$61-$V$62))*($V$65-$V$64) -> #DIV/0! | X20: =(G20*0.5)+(H20*0.15)+(U20*0.1)+(W20*0.25) -> #DIV/0!
A21: 12 | B21: 222301013 | C21: RAHMITA KUSUMA | E21: √ | F21: ACP | G21: 80 | H21: 90 | I21: 82 | J21: 81 | K21: 88 | L21: =AVERAGE(J21:K21) -> 84.5 | M21: =$N$64+((N21-$N$62)/($N$61-$N$62))*($N$65-$N$64) -> 87 | N21: =(0.1*G21)+(0.5*H21)+(0.15*I21)+(0.25*L21) -> 86.425 | P21: =I21 -> 82 | Q21: 0 | R21: =$S$64+((S21-$S$62)/($S$61-$S$62))*($S$65-$S$64) -> 87 | S21: =(0.1*G21)+(0.5*H21)+(0.15*P21)+(0.25*Q21) -> 65.3 | U21: 0 | V21: 0 | W21: =$V$64+((V21-$V$62)/($V$61-$V$62))*($V$65-$V$64) -> #DIV/0! | X21: =(G21*0.5)+(H21*0.15)+(U21*0.1)+(W21*0.25) -> #DIV/0!
A22: 13 | B22: 222301014 | C22: RENDI DAMARA | D22: √ | F22: ACP | G22: 80 | H22: 85 | I22: 83 | J22: 81 | K22: 85 | L22: =AVERAGE(J22:K22) -> 83 | M22: =$N$64+((N22-$N$62)/($N$61-$N$62))*($N$65-$N$64) -> 86.52193 | N22: =(0.1*G22)+(0.5*H22)+(0.15*I22)+(0.25*L22) -> 83.7 | P22: =I22 -> 83 | Q22: 0 | R22: =$S$64+((S22-$S$62)/($S$61-$S$62))*($S$65-$S$64) -> 86.509565 | S22: =(0.1*G22)+(0.5*H22)+(0.15*P22)+(0.25*Q22) -> 62.95 | U22: 0 | V22: 0 | W22: =$V$64+((V22-$V$62)/($V$61-$V$62))*($V$65-$V$64) -> #DIV/0! | X22: =(G22*0.5)+(H22*0.15)+(U22*0.1)+(W22*0.25) -> #DIV/0!
A23: 14 | B23: 222301015 | C23: SALMA RAHMITA | E23: √ | F23: ACP | G23: 77 | H23: 77 | I23: 0 | J23: 81 | K23: 70 | L23: =AVERAGE(J23:K23) -> 75.5 | M23: =$N$64+((N23-$N$62)/($N$61-$N$62))*($N$65-$N$64) -> 83.254386 | N23: =(0.1*G23)+(0.5*H23)+(0.15*I23)+(0.25*L23) -> 65.075 | P23: =I23 -> 0 | Q23: 0 | R23: =$S$64+((S23-$S$62)/($S$61-$S$62))*($S$65-$S$64) -> 83.013913 | S23: =(0.1*G23)+(0.5*H23)+(0.15*P23)+(0.25*Q23) -> 46.2 | U23: 0 | V23: 0 | W23: =$V$64+((V23-$V$62)/($V$61-$V$62))*($V$65-$V$64) -> #DIV/0! | X23: =(G23*0.5)+(H23*0.15)+(U23*0.1)+(W23*0.25) -> #DIV/0!
A24: 15 | B24: 222301017 | C24: ANISA LEGINA PUTRI | E24: √ | F24: RPL | G24: 83 | H24: 12 | I24: 78 | J24: 83 | K24: 82 | L24: =AVERAGE(J24:K24) -> 82.5 | M24: =$N$64+((N24-$N$62)/($N$61-$N$62))*($N$65-$N$64) -> 80.017544 | N24: =(0.1*G24)+(0.5*H24)+(0.15*I24)+(0.25*L24) -> 46.625 | P24: =I24 -> 78 | Q24: 0 | R24: =$S$64+((S24-$S$62)/($S$61-$S$62))*($S$65-$S$64) -> 78.798261 | S24: =(0.1*G24)+(0.5*H24)+(0.15*P24)+(0.25*Q24) -> 26 | U24: 0 | V24: 0 | W24: =$V$64+((V24-$V$62)/($V$61-$V$62))*($V$65-$V$64) -> #DIV/0! | X24: =(G24*0.5)+(H24*0.15)+(U24*0.1)+(W24*0.25) -> #DIV/0!
A25: 16 | B25: 222301018 | C25: ASIH | E25: √ | F25: RPL | G25: 83 | H25: 35 | I25: 20 | J25: 81 | K25: 88 | L25: =AVERAGE(J25:K25) -> 84.5 | M25: =$N$64+((N25-$N$62)/($N$61-$N$62))*($N$65-$N$64) -> 80.596491 | N25: =(0.1*G25)+(0.5*H25)+(0.15*I25)+(0.25*L25) -> 49.925 | P25: =I25 -> 20 | Q25: 0 | R25: =$S$64+((S25-$S$62)/($S$61-$S$62))*($S$65-$S$64) -> 79.382609 | S25: =(0.1*G25)+(0.5*H25)+(0.15*P25)+(0.25*Q25) -> 28.8 | U25: 0 | V25: 0 | W25: =$V$64+((V25-$V$62)/($V$61-$V$62))*($V$65-$V$64) -> #DIV/0! | X25: =(G25*0.5)+(H25*0.15)+(U25*0.1)+(W25*0.25) -> #DIV/0!
A26: 17 | B26: 222301019 | C26: DESVITA AWALIADI | E26: √ | F26: RPL | G26: 83 | H26: 62 | I26: 60 | J26: 79 | K26: 81 | L26: =AVERAGE(J26:K26) -> 80 | M26: =$N$64+((N26-$N$62)/($N$61-$N$62))*($N$65-$N$64) -> 83.820175 | N26: =(0.1*G26)+(0.5*H26)+(0.15*I26)+(0.25*L26) -> 68.3 | P26: =I26 -> 60 | Q26: 0 | R26: =$S$64+((S26-$S$62)/($S$61-$S$62))*($S$65-$S$64) -> 83.452174 | S26: =(0.1*G26)+(0.5*H26)+(0.15*P26)+(0.25*Q26) -> 48.3 | U26: 0 | V26: 0 | W26: =$V$64+((V26-$V$62)/($V$61-$V$62))*($V$65-$V$64) -> #DIV/0! | X26: =(G26*0.5)+(H26*0.15)+(U26*0.1)+(W26*0.25) -> #DIV/0!
A27: 18 | B27: 222301020 | C27: DIMAS ADITYA WIJAYA | D27: √ | F27: RPL | G27: 79 | H27: 39 | I27: 25 | J27: 79 | K27: 85 | L27: =AVERAGE(J27:K27) -> 82 | M27: =$N$64+((N27-$N$62)/($N$61-$N$62))*($N$65-$N$64) -> 80.899123 | N27: =(0.1*G27)+(0.5*H27)+(0.15*I27)+(0.25*L27) -> 51.65 | P27: =I27 -> 25 | Q27: 0 | R27: =$S$64+((S27-$S$62)/($S$61-$S$62))*($S$65-$S$64) -> 79.873043 | S27: =(0.1*G27)+(0.5*H27)+(0.15*P27)+(0.25*Q27) -> 31.15 | U27: 0 | V27: 0 | W27: =$V$64+((V27-$V$62)/($V$61-$V$62))*($V$65-$V$64) -> #DIV/0! | X27: =(G27*0.5)+(H27*0.15)+(U27*0.1)+(W27*0.25) -> #DIV/0! | AB27: SENIN
A28: 19 | B28: 222301021 | C28: DIMAS MAULANA | D28: √ | F28: RPL | G28: 83 | H28: 23 | I28: 42 | J28: 81 | K28: 0 | L28: =AVERAGE(J28:K28) -> 40.5 | M28: =$N$64+((N28-$N$62)/($N$61-$N$62))*($N$65-$N$64) -> 78.192982 | N28: =(0.1*G28)+(0.5*H28)+(0.15*I28)+(0.25*L28) -> 36.225 | P28: =I28 -> 42 | Q28: 0 | R28: =$S$64+((S28-$S$62)/($S$61-$S$62))*($S$65-$S$64) -> 78.81913 | S28: =(0.1*G28)+(0.5*H28)+(0.15*P28)+(0.25*Q28) -> 26.1 | U28: 0 | V28: 0 | W28: =$V$64+((V28-$V$62)/($V$61-$V$62))*($V$65-$V$64) -> #DIV/0! | X28: =(G28*0.5)+(H28*0.15)+(U28*0.1)+(W28*0.25) -> #DIV/0!
A29: 20 | B29: 222301023 | C29: FARHAN AZIZI | D29: √ | F29: RPL | G29: 83 | H29: 35 | I29: 36 | J29: 67 | K29: 82 | L29: =AVERAGE(J29:K29) -> 74.5 | M29: =$N$64+((N29-$N$62)/($N$61-$N$62))*($N$65-$N$64) -> 80.578947 | N29: =(0.1*G29)+(0.5*H29)+(0.15*I29)+(0.25*L29) -> 49.825 | P29: =I29 -> 36 | Q29: 0 | R29: =$S$64+((S29-$S$62)/($S$61-$S$62))*($S$65-$S$64) -> 79.883478 | S29: =(0.1*G29)+(0.5*H29)+(0.15*P29)+(0.25*Q29) -> 31.2 | U29: 0 | V29: 0 | W29: =$V$64+((V29-$V$62)/($V$61-$V$62))*($V$65-$V$64) -> #DIV/0! | X29: =(G29*0.5)+(H29*0.15)+(U29*0.1)+(W29*0.25) -> #DIV/0!
A30: 21 | B30: 222301024 | C30: HIJKIL HAIKAL | D30: √ | F30: RPL | G30: 78 | H30: 0 | I30: 0 | J30: 83 | K30: 0 | L30: =AVERAGE(J30:K30) -> 41.5 | M30: =$N$64+((N30-$N$62)/($N$61-$N$62))*($N$65-$N$64) -> 75.026316 | N30: =(0.1*G30)+(0.5*H30)+(0.15*I30)+(0.25*L30) -> 18.175 | P30: =I30 -> 0 | Q30: 0 | R30: =$S$64+((S30-$S$62)/($S$61-$S$62))*($S$65-$S$64) -> 75 | S30: =(0.1*G30)+(0.5*H30)+(0.15*P30)+(0.25*Q30) -> 7.8 | U30: 0 | V30: 0 | W30: =$V$64+((V30-$V$62)/($V$61-$V$62))*($V$65-$V$64) -> #DIV/0! | X30: =(G30*0.5)+(H30*0.15)+(U30*0.1)+(W30*0.25) -> #DIV/0!
A31: 22 | B31: 222301025 | C31: INDRI OKTAPIANI | E31: √ | F31: RPL | G31: 83 | H31: 24 | I31: 72 | J31: 79 | K31: 85 | L31: =AVERAGE(J31:K31) -> 82 | M31: =$N$64+((N31-$N$62)/($N$61-$N$62))*($N$65-$N$64) -> 80.890351 | N31: =(0.1*G31)+(0.5*H31)+(0.15*I31)+(0.25*L31) -> 51.6 | P31: =I31 -> 72 | Q31: 0 | R31: =$S$64+((S31-$S$62)/($S$61-$S$62))*($S$65-$S$64) -> 79.862609 | S31: =(0.1*G31)+(0.5*H31)+(0.15*P31)+(0.25*Q31) -> 31.1 | U31: 0 | V31: 0 | W31: =$V$64+((V31-$V$62)/($V$61-$V$62))*($V$65-$V$64) -> #DIV/0! | X31: =(G31*0.5)+(H31*0.15)+(U31*0.1)+(W31*0.25) -> #DIV/0!
A32: 23 | B32: 222301026 | C32: JIBRIEL ABDILLAH | D32: √ | F32: RPL | G32: 83 | H32: 91 | I32: 48 | J32: 77 | K32: 88 | L32: =AVERAGE(J32:K32) -> 82.5 | M32: =$N$64+((N32-$N$62)/($N$61-$N$62))*($N$65-$N$64) -> 86.157895 | N32: =(0.1*G32)+(0.5*H32)+(0.15*I32)+(0.25*L32) -> 81.625 | P32: =I32 -> 48 | Q32: 0 | R32: =$S$64+((S32-$S$62)/($S$61-$S$62))*($S$65-$S$64) -> 86.102609 | S32: =(0.1*G32)+(0.5*H32)+(0.15*P32)+(0.25*Q32) -> 61 | U32: 0 | V32: 0 | W32: =$V$64+((V32-$V$62)/($V$61-$V$62))*($V$65-$V$64) -> #DIV/0! | X32: =(G32*0.5)+(H32*0.15)+(U32*0.1)+(W32*0.25) -> #DIV/0! | AC32: SENIN
A33: 24 | B33: 222301027 | C33: KESIT TRIAS CHANDRA WIGUNA | D33: √ | F33: RPL | G33: 83 | H33: 53 | I33: 54 | J33: 79 | K33: 88 | L33: =AVERAGE(J33:K33) -> 83.5 | M33: =$N$64+((N33-$N$62)/($N$61-$N$62))*($N$65-$N$64) -> 83.026316 | N33: =(0.1*G33)+(0.5*H33)+(0.15*I33)+(0.25*L33) -> 63.775 | P33: =I33 -> 54 | Q33: 0 | R33: =$S$64+((S33-$S$62)/($S$61-$S$62))*($S$65-$S$64) -> 82.325217 | S33: =(0.1*G33)+(0.5*H33)+(0.15*P33)+(0.25*Q33) -> 42.9 | U33: 0 | V33: 0 | W33: =$V$64+((V33-$V$62)/($V$61-$V$62))*($V$65-$V$64) -> #DIV/0! | X33: =(G33*0.5)+(H33*0.15)+(U33*0.1)+(W33*0.25) -> #DIV/0!
A34: 25 | B34: 222301028 | C34: LENTI FATMAWATI | E34: √ | F34: RPL | G34: 83 | H34: 13 | I34: 78 | J34: 81 | K34: 88 | L34: =AVERAGE(J34:K34) -> 84.5 | M34: =$N$64+((N34-$N$62)/($N$61-$N$62))*($N$65-$N$64) -> 80.192982 | N34: =(0.1*G34)+(0.5*H34)+(0.15*I34)+(0.25*L34) -> 47.625 | P34: =I34 -> 78 | Q34: 0 | R34: =$S$64+((S34-$S$62)/($S$61-$S$62))*($S$65-$S$64) -> 78.902609 | S34: =(0.1*G34)+(0.5*H34)+(0.15*P34)+(0.25*Q34) -> 26.5 | U34: 0 | V34: 0 | W34: =$V$64+((V34-$V$62)/($V$61-$V$62))*($V$65-$V$64) -> #DIV/0! | X34: =(G34*0.5)+(H34*0.15)+(U34*0.1)+(W34*0.25) -> #DIV/0!
A35: 26 | B35: 222301029 | C35: MARSHA AMIRA ZAHRA | E35: √ | F35: RPL | G35: 83 | H35: 34 | I35: 48 | J35: 81 | K35: 78 | L35: =AVERAGE(J35:K35) -> 79.5 | M35: =$N$64+((N35-$N$62)/($N$61-$N$62))*($N$65-$N$64) -> 81.026316 | N35: =(0.1*G35)+(0.5*H35)+(0.15*I35)+(0.25*L35) -> 52.375 | P35: =I35 -> 48 | Q35: 0 | R35: =$S$64+((S35-$S$62)/($S$61-$S$62))*($S$65-$S$64) -> 80.154783 | S35: =(0.1*G35)+(0.5*H35)+(0.15*P35)+(0.25*Q35) -> 32.5 | U35: 0 | V35: 0 | W35: =$V$64+((V35-$V$62)/($V$61-$V$62))*($V$65-$V$64) -> #DIV/0! | X35: =(G35*0.5)+(H35*0.15)+(U35*0.1)+(W35*0.25) -> #DIV/0!
A36: 27 | B36: 222301031 | C36: MUHAMAD BAYU ROJUDIN | D36: √ | F36: RPL | G36: 77 | H36: 10 | I36: 36 | J36: 0 | K36: 70 | L36: =AVERAGE(J36:K36) -> 35 | M36: =$N$64+((N36-$N$62)/($N$61-$N$62))*($N$65-$N$64) -> 76.548246 | N36: =(0.1*G36)+(0.5*H36)+(0.15*I36)+(0.25*L36) -> 26.85 | P36: =I36 -> 36 | Q36: 0 | R36: =$S$64+((S36-$S$62)/($S$61-$S$62))*($S$65-$S$64) -> 77.149565 | S36: =(0.1*G36)+(0.5*H36)+(0.15*P36)+(0.25*Q36) -> 18.1 | U36: 0 | V36: 0 | W36: =$V$64+((V36-$V$62)/($V$61-$V$62))*($V$65-$V$64) -> #DIV/0! | X36: =(G36*0.5)+(H36*0.15)+(U36*0.1)+(W36*0.25) -> #DIV/0!
A37: 28 | B37: 222301032 | C37: MUHAMMAD ALFARIZKI | D37: √ | F37: RPL | G37: 77 | H37: 24 | I37: 42 | J37: 0 | K37: 88 | L37: =AVERAGE(J37:K37) -> 44 | M37: =$N$64+((N37-$N$62)/($N$61-$N$62))*($N$65-$N$64) -> 78.328947 | N37: =(0.1*G37)+(0.5*H37)+(0.15*I37)+(0.25*L37) -> 37 | P37: =I37 -> 42 | Q37: 0 | R37: =$S$64+((S37-$S$62)/($S$61-$S$62))*($S$65-$S$64) -> 78.798261 | S37: =(0.1*G37)+(0.5*H37)+(0.15*P37)+(0.25*Q37) -> 26 | U37: 0 | V37: 0 | W37: =$V$64+((V37-$V$62)/($V$61-$V$62))*($V$65-$V$64) -> #DIV/0! | X37: =(G37*0.5)+(H37*0.15)+(U37*0.1)+(W37*0.25) -> #DIV/0!
A38: 29 | B38: 222301033 | C38: MUHAMMAD FAHMI IRAWAN | D38: √ | F38: RPL | G38: 83 | H38: 34 | I38: 42 | J38: 83 | K38: 0 | L38: =AVERAGE(J38:K38) -> 41.5 | M38: =$N$64+((N38-$N$62)/($N$61-$N$62))*($N$65-$N$64) -> 79.201754 | N38: =(0.1*G38)+(0.5*H38)+(0.15*I38)+(0.25*L38) -> 41.975 | P38: =I38 -> 42 | Q38: 0 | R38: =$S$64+((S38-$S$62)/($S$61-$S$62))*($S$65-$S$64) -> 79.966957 | S38: =(0.1*G38)+(0.5*H38)+(0.15*P38)+(0.25*Q38) -> 31.6 | U38: 0 | V38: 0 | W38: =$V$64+((V38-$V$62)/($V$61-$V$62))*($V$65-$V$64) -> #DIV/0! | X38: =(G38*0.5)+(H38*0.15)+(U38*0.1)+(W38*0.25) -> #DIV/0!
A39: 30 | B39: 222301035 | C39: NENG MELA MELYANI | E39: √ | F39: RPL | G39: 83 | H39: 24 | I39: 18 | J39: 79 | K39: 85 | L39: =AVERAGE(J39:K39) -> 82 | M39: =$N$64+((N39-$N$62)/($N$61-$N$62))*($N$65-$N$64) -> 79.469298 | N39: =(0.1*G39)+(0.5*H39)+(0.15*I39)+(0.25*L39) -> 43.5 | P39: =I39 -> 18 | Q39: 0 | R39: =$S$64+((S39-$S$62)/($S$61-$S$62))*($S$65-$S$64) -> 78.172174 | S39: =(0.1*G39)+(0.5*H39)+(0.15*P39)+(0.25*Q39) -> 23 | U39: 0 | V39: 0 | W39: =$V$64+((V39-$V$62)/($V$61-$V$62))*($V$65-$V$64) -> #DIV/0! | X39: =(G39*0.5)+(H39*0.15)+(U39*0.1)+(W39*0.25) -> #DIV/0!
A40: 31 | B40: 222301036 | C40: NURYANA | D40: √ | F40: RPL | G40: 83 | H40: 23 | I40: 24 | J40: 49 | K40: 79 | L40: =AVERAGE(J40:K40) -> 64 | M40: =$N$64+((N40-$N$62)/($N$61-$N$62))*($N$65-$N$64) -> 78.75 | N40: =(0.1*G40)+(0.5*H40)+(0.15*I40)+(0.25*L40) -> 39.4 | P40: =I40 -> 24 | Q40: 0 | R40: =$S$64+((S40-$S$62)/($S$61-$S$62))*($S$65-$S$64) -> 78.255652 | S40: =(0.1*G40)+(0.5*H40)+(0.15*P40)+(0.25*Q40) -> 23.4 | U40: 0 | V40: 0 | W40: =$V$64+((V40-$V$62)/($V$61-$V$62))*($V$65-$V$64) -> #DIV/0! | X40: =(G40*0.5)+(H40*0.15)+(U40*0.1)+(W40*0.25) -> #DIV/0!
A41: 32 | B41: 222301037 | C41: PUTRI FIRYAL | E41: √ | F41: RPL | G41: 79 | H41: 46 | I41: 42 | J41: 79 | K41: 85 | L41: =AVERAGE(J41:K41) -> 82 | M41: =$N$64+((N41-$N$62)/($N$61-$N$62))*($N$65-$N$64) -> 81.960526 | N41: =(0.1*G41)+(0.5*H41)+(0.15*I41)+(0.25*L41) -> 57.7 | P41: =I41 -> 42 | Q41: 0 | R41: =$S$64+((S41-$S$62)/($S$61-$S$62))*($S$65-$S$64) -> 81.135652 | S41: =(0.1*G41)+(0.5*H41)+(0.15*P41)+(0.25*Q41) -> 37.2 | U41: 0 | V41: 0 | W41: =$V$64+((V41-$V$62)/($V$61-$V$62))*($V$65-$V$64) -> #DIV/0! | X41: =(G41*0.5)+(H41*0.15)+(U41*0.1)+(W41*0.25) -> #DIV/0!
...

Sheet PERBAIKAN
A1: DATA PESERTA PERBAIKAN MATA PELAJARAN ASEP SUKANDAR
A4: Catatan : Diharap Baca Intruksi Dengan Teliti Batas Pengumpulan Tanggal : 16 Desember 2024, Pukul : 11.00 WIB
A6: NO | B6: NAMA | C6: KELAS | D6: PERBAIKAN NILAI | H6: LINK PERBAIKAN | K6: PENGUMPULAN | L6: EMAIL
A7: 1 | B7: AKBAR MAULANA | C7: X ACP | F7: PAS PRAKTIK | H7: PTS | I7: X | J7: https://drive.google.com/file/d/1xXaYKCSKix5OrXFt4Wg_vq3_OJu7PNS5/view?usp=sharing | K7: Polio dan kumpulkan ke email dengan Subjek PERBAIKAN_NAMA | L7: asep.sukandar_ti23@nusaputra.ac.id
A8: 2 | B8: FADIL ABDUL AZIZ | C8: X ACP | F8: PAS PRAKTIK | H8: PAS TEORI | J8: https://forms.gle/VkQ9jAutdyyVSrRy9 | K8: Kerjakan di Link Ini
A9: 3 | B9: RIVQI WILIAWAN | C9: X ACP | F9: PAS PRAKTIK | H9: PAS PRAKTIK | J9: https://docs.google.com/document/d/1MHeRHOzAMJEYvChLAc_uu07o8lbRcaVR/edit?usp=sharing&ouid=101016139641050089899&rtpof=true&sd=true | K9: Kumpulkan Bentuk Laporan Dokumentasi ke email dengan Subjek PERBAIKAN_NAMA
A10: 4 | B10: DAVIN ARYA PUTRA | C10: X RPL | F10: PAS PRAKTIK | H10: PTS | I10: XI | J10: https://drive.google.com/file/d/1hLlGreWXfloQwmqPWYOGHMTJaSWSFsEz/view?usp=sharing | K10: Polio dan kumpulkan ke email dengan Subjek PERBAIKAN_NAMA
A11: 5 | B11: FARIZ ALBA | C11: X RPL | F11: PAS PRAKTIK | H11: PAS TEORI | J11: https://forms.gle/bBsrjHg82jKRh68A8 | K11: Kerjakan di Link Ini
A12: 6 | B12: HAIKAL BUDIANSYAH | C12: X RPL | D12: PTS | F12: PAS PRAKTIK | H12: PAS PRAKTIK | J12: https://docs.google.com/document/d/1pPP9cElu0zwIUXlkV7aiyfEmBTsWTdRi/edit?usp=sharing&ouid=101016139641050089899&rtpof=true&sd=true | K12: Kumpulkan Bentuk Laporan Dokumentasi ke email dengan Subjek PERBAIKAN_NAMA
A13: 7 | B13: INDRIYANI FITRIYASARI | C13: X RPL | D13: PTS | H13: PTS | I13: XII | J13: https://docs.google.com/document/d/1XccgmYizPI0QG7Tyu2hWjUbcWT9xTQPi/edit?usp=sharing&ouid=101016139641050089899&rtpof=true&sd=true | K13: Polio dan kumpulkan ke email dengan Subjek PERBAIKAN_NAMA
A14: 8 | B14: JANPETER SEBASTIAN PANDIANGAN | C14: X RPL | F14: PAS PRAKTIK | H14: PAS TEORI | J14: https://forms.gle/CKHzK4cVAiwesrkw6 | K14: Kerjakan di Link Ini
A15: 9 | B15: M. RUSTANDI | C15: X RPL | D15: PTS | H15: PAS PRAKTIK | J15: https://drive.google.com/file/d/1VQUNEPxUM0mi_NE6Vb0IX9BrMnr0OfSU/view?usp=sharing | K15: Kumpulkan Bentuk Laporan Dokumentasi ke email dengan Subjek PERBAIKAN_NAMA
A16: 10 | B16: MOCH PAISAL LUTHFI | C16: X RPL | F16: PAS PRAKTIK
A17: 11 | B17: RAKA CANDRA FADILAH | C17: X RPL | E17: PAS TEORI
A18: 12 | B18: SRI RESTI RAMDAN | C18: X RPL | D18: PTS
A19: 13 | B19: CIKAL PUTRA SUBRANI | C19: XI ACP | D19: PTS | F19: PAS PRAKTIK
A20: 14 | B20: ENENG SALSA NABILA | C20: XI ACP | F20: PAS PRAKTIK
A21: 15 | B21: HERMAWAN ANGGARA | C21: XI ACP | F21: PAS PRAKTIK
A22: 16 | B22: JANNATA TSAMANIYA ARSYISTAWAA | C22: XI ACP | F22: PAS PRAKTIK
A23: 17 | B23: KURNIASANDI AUNURRAFIQ | C23: XI ACP | E23: PAS TEORI
A24: 18 | B24: REY GUSTIAWAN | C24: XI ACP | F24: PAS PRAKTIK
A25: 19 | B25: SITI HASANAH | C25: XI ACP | F25: PAS PRAKTIK
A26: 20 | B26: SURYANA | C26: XI ACP | E26: PAS TEORI | F26: PAS PRAKTIK
A27: 21 | B27: TIARA AMANDA PUTRI FATRIANA | C27: XI ACP | F27: PAS PRAKTIK
A28: 22 | B28: ABDUL HAKIM | C28: XI RPL | F28: PAS PRAKTIK
A29: 23 | B29: AGIL AL PAUJI | C29: XI RPL | D29: PTS | F29: PAS PRAKTIK
A30: 24 | B30: ALI AKBAR NUR SUBHKI | C30: XI RPL | D30: PTS
A31: 25 | B31: ARDIANSYAH | C31: XI RPL | F31: PAS PRAKTIK
A32: 26 | B32: IKHSAN ALFANDI PRATAMA | C32: XI RPL | F32: PAS PRAKTIK
A33: 27 | B33: KIREINA NARZILLA IRAWAN | C33: XI RPL | F33: PAS PRAKTIK
